Workbook
Name UPDATE: 'Data Sheet'!$E$1

Sheet Profit & Loss
A1: ='Data Sheet'!B1 -> HDFC BANK LTD | H1: =UPDATE | M1: SCREENER.IN
A3: Narration | B3: ='Data Sheet'!B16 -> 42460 | C3: ='Data Sheet'!C16 -> 42825 | D3: ='Data Sheet'!D16 -> 43190 | E3: ='Data Sheet'!E16 -> 43555 | F3: ='Data Sheet'!F16 -> 43921 | G3: ='Data Sheet'!G16 -> 44286 | H3: ='Data Sheet'!H16 -> 44651 | I3: ='Data Sheet'!I16 -> 45016 | ... K3: ='Data Sheet'!K16 -> 45747 | L3: Trailing | M3: Best Case | N3: Worst Case
A4: Sales | B4: ='Data Sheet'!B17 -> 63161.56 | C4: ='Data Sheet'!C17 -> 73271.35 | D4: ='Data Sheet'!D17 -> 85287.84 | E4: ='Data Sheet'!E17 -> 105160.74 | F4: ='Data Sheet'!F17 -> 122189.29 | G4: ='Data Sheet'!G17 -> 128552.4 | H4: ='Data Sheet'!H17 -> 135936.41 | I4: ='Data Sheet'!I17 -> 170754.05 | ... K4: ='Data Sheet'!K17 -> 336367.43 | L4: =SUM(Quarters!H4:K4) -> 346185.22 | M4: =$K4+M23*K4 -> 454960.11 | N4: =$K4+N23*L4 -> 400708.69
A5: Expenses | B5: =SUM('Data Sheet'!B18,'Data Sheet'!B20:B24, -1*'Data Sheet'!B19) -> 20054.62 | C5: =SUM('Data Sheet'!C18,'Data Sheet'!C20:C24, -1*'Data Sheet'!C19) -> 23855.69 | D5: =SUM('Data Sheet'!D18,'Data Sheet'!D20:D24, -1*'Data Sheet'!D19) -> 29532.26 | E5: =SUM('Data Sheet'!E18,'Data Sheet'!E20:E24, -1*'Data Sheet'!E19) -> 34856.27 | F5: =SUM('Data Sheet'!F18,'Data Sheet'!F20:F24, -1*'Data Sheet'!F19) -> 45459.21 | G5: =SUM('Data Sheet'!G18,'Data Sheet'!G20:G24, -1*'Data Sheet'!G19) -> 52456.53 | H5: =SUM('Data Sheet'!H18,'Data Sheet'!H20:H24, -1*'Data Sheet'!H19) -> 56556.96 | I5: =SUM('Data Sheet'!I18,'Data Sheet'!I20:I24, -1*'Data Sheet'!I19) -> 63042.3 | ... K5: =SUM('Data Sheet'!K18,'Data Sheet'!K20:K24, -1*'Data Sheet'!K19) -> 186974.45 | L5: =SUM(Quarters!H5:K5) -> 198673.46 | M5: =M4-M6 -> 244065.34 | N5: =N4-N6 -> 229964.13
A6: Operating Profit | B6: =B4-B5 -> 43106.94 | C6: =C4-C5 -> 49415.66 | D6: =D4-D5 -> 55755.58 | E6: =E4-E5 -> 70304.47 | F6: =F4-F5 -> 76730.08 | G6: =G4-G5 -> 76095.87 | H6: =H4-H5 -> 79379.45 | I6: =I4-I5 -> 107711.75 | ... K6: =K4-K5 -> 149392.98 | L6: =SUM(Quarters!H6:K6) -> 147511.76 | M6: =M4*M24 -> 210894.77 | N6: =N4*N24 -> 170744.56
A7: Other Income | B7: ='Data Sheet'!B25 -> 11211.65 | C7: ='Data Sheet'!C25 -> 12905.08 | D7: ='Data Sheet'!D25 -> 16056.6 | E7: ='Data Sheet'!E25 -> 18947.05 | F7: ='Data Sheet'!F25 -> 24878.97 | G7: ='Data Sheet'!G25 -> 27332.88 | H7: ='Data Sheet'!H25 -> 31758.99 | I7: ='Data Sheet'!I25 -> 33912.05 | ... K7: ='Data Sheet'!K25 -> 134548.5 | L7: =SUM(Quarters!H7:K7) -> 137893.08 | M7: 0 | N7: 0
A8: Depreciation | B8: ='Data Sheet'!B26 -> 738.03 | C8: ='Data Sheet'!C26 -> 886.19 | D8: ='Data Sheet'!D26 -> 966.78 | E8: ='Data Sheet'!E26 -> 1220.67 | F8: ='Data Sheet'!F26 -> 1276.77 | G8: ='Data Sheet'!G26 -> 1385.01 | H8: ='Data Sheet'!H26 -> 1680.73 | I8: ='Data Sheet'!I26 -> 2345.47 | ... K8: ='Data Sheet'!K26 -> 3805.23 | L8: =SUM(Quarters!H8:K8) -> 0 | M8: =+$L8 -> 0 | N8: =+$L8 -> 0
A9: Interest | B9: ='Data Sheet'!B27 -> 34069.57 | C9: ='Data Sheet'!C27 -> 38041.58 | D9: ='Data Sheet'!D27 -> 42381.48 | E9: ='Data Sheet'!E27 -> 53712.69 | F9: ='Data Sheet'!F27 -> 62137.42 | G9: ='Data Sheet'!G27 -> 59247.59 | H9: ='Data Sheet'!H27 -> 58584.33 | I9: ='Data Sheet'!I27 -> 77779.94 | ... K9: ='Data Sheet'!K27 -> 183894.2 | L9: =SUM(Quarters!H9:K9) -> 188349.86 | M9: =+$L9 -> 188349.86 | N9: =+$L9 -> 188349.86
A10: Profit before tax | B10: ='Data Sheet'!B28 -> 19510.99 | C10: ='Data Sheet'!C28 -> 23392.97 | D10: ='Data Sheet'!D28 -> 28463.92 | E10: ='Data Sheet'!E28 -> 34318.16 | F10: ='Data Sheet'!F28 -> 38194.86 | G10: ='Data Sheet'!G28 -> 42796.15 | H10: ='Data Sheet'!H28 -> 50873.38 | I10: ='Data Sheet'!I28 -> 61498.39 | ... K10: ='Data Sheet'!K28 -> 96242.05 | L10: =SUM(Quarters!H10:K10) -> 97054.98 | M10: =M6+M7-SUM(M8:M9) -> 22544.91 | N10: =N6+N7-SUM(N8:N9) -> -17605.298
A11: Tax | B11: ='Data Sheet'!B29 -> 6693.66 | C11: ='Data Sheet'!C29 -> 8078.12 | D11: ='Data Sheet'!D29 -> 9903.08 | E11: ='Data Sheet'!E29 -> 11872.55 | F11: ='Data Sheet'!F29 -> 10898.59 | G11: ='Data Sheet'!G29 -> 10939.38 | H11: ='Data Sheet'!H29 -> 12722.48 | I11: ='Data Sheet'!I29 -> 15349.69 | ... K11: ='Data Sheet'!K29 -> 22801.88 | L11: =SUM(Quarters!H11:K11) -> 21976.1 | M11: =IF($L10>0,$L11/$L10,0) -> 0.22642939 | N11: =IF($L10>0,$L11/$L10,0) -> 0.22642939
A12: Net profit | B12: ='Data Sheet'!B30 -> 12801.33 | C12: ='Data Sheet'!C30 -> 15280.48 | D12: ='Data Sheet'!D30 -> 18510.02 | E12: ='Data Sheet'!E30 -> 22332.43 | F12: ='Data Sheet'!F30 -> 27253.95 | G12: ='Data Sheet'!G30 -> 31833.21 | H12: ='Data Sheet'!H30 -> 38052.75 | I12: ='Data Sheet'!I30 -> 45997.11 | ... K12: ='Data Sheet'!K30 -> 70792.25 | L12: =SUM(Quarters!H12:K12) -> 72360.07 | M12: =M10-M11*M10 -> 17440.079 | N12: =N10-N11*N10 -> -13618.941
A13: EPS | B13: =IF('Data Sheet'!B93>0,B12/'Data Sheet'!B93,0) -> 12.658542 | C13: =IF('Data Sheet'!C93>0,C12/'Data Sheet'!C93,0) -> 14.907494 | D13: =IF('Data Sheet'!D93>0,D12/'Data Sheet'!D93,0) -> 17.831702 | E13: =IF('Data Sheet'!E93>0,E12/'Data Sheet'!E93,0) -> 20.501258 | F13: =IF('Data Sheet'!F93>0,F12/'Data Sheet'!F93,0) -> 24.851777 | G13: =IF('Data Sheet'!G93>0,G12/'Data Sheet'!G93,0) -> 28.872089 | H13: =IF('Data Sheet'!H93>0,H12/'Data Sheet'!H93,0) -> 34.309266 | I13: =IF('Data Sheet'!I93>0,I12/'Data Sheet'!I93,0) -> 41.217895 | ... K13: =IF('Data Sheet'!K93>0,K12/'Data Sheet'!K93,0) -> 46.256142 | L13: =IF('Data Sheet'!$B6>0,'Profit & Loss'!L12/'Data Sheet'!$B6,0) -> 47.028675 | M13: =IF('Data Sheet'!$B6>0,'Profit & Loss'!M12/'Data Sheet'!$B6,0) -> 11.334757 | N13: =IF('Data Sheet'!$B6>0,'Profit & Loss'!N12/'Data Sheet'!$B6,0) -> -8.8513012
A14: Price to earning | B14: =IF(B15>0,B15/B13,"") -> 21.154886 | C14: =IF(C15>0,C15/C13,"") -> 24.191859 | D14: =IF(D15>0,D15/D13,"") -> 26.443353 | E14: =IF(E15>0,E15/E13,"") -> 28.277777 | F14: =IF(F15>0,F15/F13,"") -> 17.340812 | G14: =IF(G15>0,G15/G13,"") -> 25.866851 | H14: =IF(H15>0,H15/H13,"") -> 21.428031 | I14: =IF(I15>0,I15/I13,"") -> 19.525015 | ... K14: =IF(K15>0,K15/K13,"") -> 19.7617 | L14: =IF(L13>0,L15/L13,0) -> 21.121156 | M14: =M25 -> 21.121156 | N14: =N25 -> 19.394506
A15: Price | B15: ='Data Sheet'!B90 -> 267.79 | C15: ='Data Sheet'!C90 -> 360.64 | D15: ='Data Sheet'!D90 -> 471.53 | E15: ='Data Sheet'!E90 -> 579.73 | F15: ='Data Sheet'!F90 -> 430.95 | G15: ='Data Sheet'!G90 -> 746.83 | H15: ='Data Sheet'!H90 -> 735.18 | I15: ='Data Sheet'!I90 -> 804.78 | ... K15: ='Data Sheet'!K90 -> 914.1 | L15: ='Data Sheet'!B8 -> 993.3 | M15: =M13*M14 -> 239.40318 | N15: =N13*N14 -> -171.66662
A17: RATIOS:
A18: Dividend Payout | B18: =IF('Data Sheet'!B30>0, 'Data Sheet'!B31/'Data Sheet'!B30, 0) -> 0.18762035 | C18: =IF('Data Sheet'!C30>0, 'Data Sheet'!C31/'Data Sheet'!C30, 0) -> 0.18447064 | D18: =IF('Data Sheet'!D30>0, 'Data Sheet'!D31/'Data Sheet'!D30, 0) -> 0.18225966 | E18: =IF('Data Sheet'!E30>0, 'Data Sheet'!E31/'Data Sheet'!E30, 0) -> 0.18291561 | F18: =IF('Data Sheet'!F30>0, 'Data Sheet'!F31/'Data Sheet'!F30, 0) -> 0.05029803 | G18: =IF('Data Sheet'!G30>0, 'Data Sheet'!G31/'Data Sheet'!G30, 0) -> 0.11256546 | H18: =IF('Data Sheet'!H30>0, 'Data Sheet'!H31/'Data Sheet'!H30, 0) -> 0.22588433 | I18: =IF('Data Sheet'!I30>0, 'Data Sheet'!I31/'Data Sheet'!I30, 0) -> 0.23048035 | ... K18: =IF('Data Sheet'!K30>0, 'Data Sheet'!K31/'Data Sheet'!K30, 0) -> 0.23780626
A19: OPM | B19: =IF(B6>0,B6/B4,0) -> 0.68248694 | C19: =IF(C6>0,C6/C4,0) -> 0.67441995 | D19: =IF(D6>0,D6/D4,0) -> 0.65373423 | E19: =IF(E6>0,E6/E4,0) -> 0.66854294 | F19: =IF(F6>0,F6/F4,0) -> 0.62796076 | G19: =IF(G6>0,G6/G4,0) -> 0.59194437 | H19: =IF(H6>0,H6/H4,0) -> 0.58394546 | I19: =IF(I6>0,I6/I4,0) -> 0.63080056 | ... L19: =IF(L6>0,L6/L4,0) -> 0.42610646
G22: TRENDS: | H22: 10 YEARS | I22: 7 YEARS | J22: 5 YEARS | K22: 3 YEARS | L22: RECENT | M22: BEST | N22: WORST
G23: Sales Growth | H23: =IF(B4=0,"",POWER($K4/B4,1/9)-1) -> 0.20422264 | I23: =IF(D4=0,"",POWER($K4/D4,1/7)-1) -> 0.21655683 | J23: =IF(F4=0,"",POWER($K4/F4,1/5)-1) -> 0.22449258 | K23: =IF(H4=0,"",POWER($K4/H4, 1/3)-1) -> 0.35256885 | L23: =IF(ISERROR(MAX(IF(J4=0,"",(K4-J4)/J4),IF(K4=0,"",(L4-K4)/K4))),"",MAX(IF(J4=0,"",(K4-J4)/J4),IF(K4=0,"",(L4-K4)/K4))) -> 0.1858579 | M23: =MAX(K23:L23) -> 0.35256885 | N23: =MIN(H23:L23) -> 0.1858579
G24: OPM | H24: =IF(SUM(B4:$K$4)=0,"",SUMPRODUCT(B19:$K$19,B4:$K$4)/SUM(B4:$K$4)) -> 0.54332906 | I24: =IF(SUM(E4:$K$4)=0,"",SUMPRODUCT(E19:$K$19,E4:$K$4)/SUM(E4:$K$4)) -> 0.52164604 | J24: =IF(SUM(G4:$K$4)=0,"",SUMPRODUCT(G19:$K$19,G4:$K$4)/SUM(G4:$K$4)) -> 0.49469692 | K24: =IF(SUM(I4:$K$4)=0, "", SUMPRODUCT(I19:$K$19,I4:$K$4)/SUM(I4:$K$4)) -> 0.46354563 | L24: =L19 -> 0.42610646 | M24: =MAX(K24:L24) -> 0.46354563 | N24: =MIN(H24:L24) -> 0.42610646
G25: Price to Earning | H25: =IF(ISERROR(AVERAGEIF(B14:$L14,">0")),"",AVERAGEIF(B14:$L14,">0")) -> 22.025599 | I25: =IF(ISERROR(AVERAGEIF(E14:$L14,">0")),"",AVERAGEIF(E14:$L14,">0")) -> 21.311437 | J25: =IF(ISERROR(AVERAGEIF(G14:$L14,">0")),"",AVERAGEIF(G14:$L14,">0")) -> 20.812151 | K25: =IF(ISERROR(AVERAGEIF(I14:$L14,">0")),"",AVERAGEIF(I14:$L14,">0")) -> 19.394506 | L25: =L14 -> 21.121156 | M25: =MAX(K25:L25) -> 21.121156 | N25: =MIN(H25:L25) -> 19.394506

Sheet Quarters
A1: ='Profit & Loss'!A1 -> HDFC BANK LTD | E1: =UPDATE | J1: SCREENER.IN
A3: Narration | B3: ='Data Sheet'!B41 -> 45107 | C3: ='Data Sheet'!C41 -> 45199 | D3: ='Data Sheet'!D41 -> 45291 | E3: ='Data Sheet'!E41 -> 45382 | F3: ='Data Sheet'!F41 -> 45473 | G3: ='Data Sheet'!G41 -> 45565 | H3: ='Data Sheet'!H41 -> 45657 | I3: ='Data Sheet'!I41 -> 45747 | ... K3: ='Data Sheet'!K41 -> 45930
A4: Sales | B4: ='Data Sheet'!B42 -> 51168.14 | C4: ='Data Sheet'!C42 -> 75039.1 | D4: ='Data Sheet'!D42 -> 78008.17 | E4: ='Data Sheet'!E42 -> 79433.61 | F4: ='Data Sheet'!F42 -> 81546.2 | G4: ='Data Sheet'!G42 -> 83001.72 | H4: ='Data Sheet'!H42 -> 85040.17 | I4: ='Data Sheet'!I42 -> 86779.34 | ... K4: ='Data Sheet'!K42 -> 86993.84
A5: Expenses | B5: ='Data Sheet'!B43 -> 18469.81 | C5: ='Data Sheet'!C43 -> 45349.33 | D5: ='Data Sheet'!D43 -> 50530.03 | E5: ='Data Sheet'!E43 -> 62938.45 | F5: ='Data Sheet'!F43 -> 49689.62 | G5: ='Data Sheet'!G43 -> 52074.11 | H5: ='Data Sheet'!H43 -> 41306.79 | I5: ='Data Sheet'!I43 -> 47709.16 | ... K5: ='Data Sheet'!K43 -> 45160.88
A6: Operating Profit | B6: ='Data Sheet'!B50 -> 32698.33 | C6: ='Data Sheet'!C50 -> 29689.77 | D6: ='Data Sheet'!D50 -> 27478.14 | E6: ='Data Sheet'!E50 -> 16495.16 | F6: ='Data Sheet'!F50 -> 31856.58 | G6: ='Data Sheet'!G50 -> 30927.61 | H6: ='Data Sheet'!H50 -> 43733.38 | I6: ='Data Sheet'!I50 -> 39070.18 | ... K6: ='Data Sheet'!K50 -> 41832.96
A7: Other Income | B7: ='Data Sheet'!B44 -> 9853.15 | C7: ='Data Sheet'!C44 -> 32527.52 | D7: ='Data Sheet'!D44 -> 37007.34 | E7: ='Data Sheet'!E44 -> 44957.74 | F7: ='Data Sheet'!F44 -> 35450.29 | G7: ='Data Sheet'!G44 -> 38455.02 | H7: ='Data Sheet'!H44 -> 27153.77 | I7: ='Data Sheet'!I44 -> 33489.42 | ... K7: ='Data Sheet'!K44 -> 31566.79
A8: Depreciation | B8: ='Data Sheet'!B45 -> 0 | C8: ='Data Sheet'!C45 -> 0 | D8: ='Data Sheet'!D45 -> 0 | E8: ='Data Sheet'!E45 -> 0 | F8: ='Data Sheet'!F45 -> 0 | G8: ='Data Sheet'!G45 -> 0 | H8: ='Data Sheet'!H45 -> 0 | I8: ='Data Sheet'!I45 -> 0 | ... K8: ='Data Sheet'!K45 -> 0
A9: Interest | B9: ='Data Sheet'!B46 -> 25954.76 | C9: ='Data Sheet'!C46 -> 41249.91 | D9: ='Data Sheet'!D46 -> 43242.37 | E9: ='Data Sheet'!E46 -> 43691.51 | F9: ='Data Sheet'!F46 -> 44579.5 | G9: ='Data Sheet'!G46 -> 45414.21 | H9: ='Data Sheet'!H46 -> 46914.28 | I9: ='Data Sheet'!I46 -> 46986.21 | ... K9: ='Data Sheet'!K46 -> 46740.86
A10: Profit before tax | B10: ='Data Sheet'!B47 -> 16596.72 | C10: ='Data Sheet'!C47 -> 20967.38 | D10: ='Data Sheet'!D47 -> 21243.11 | E10: ='Data Sheet'!E47 -> 17761.39 | F10: ='Data Sheet'!F47 -> 22727.37 | G10: ='Data Sheet'!G47 -> 23968.42 | H10: ='Data Sheet'!H47 -> 23972.87 | I10: ='Data Sheet'!I47 -> 25573.39 | ... K10: ='Data Sheet'!K47 -> 26658.89
A11: Tax | B11: ='Data Sheet'!B48 -> 4193.47 | C11: ='Data Sheet'!C48 -> 3655 | D11: ='Data Sheet'!D48 -> 3525.11 | E11: ='Data Sheet'!E48 -> -251.48 | F11: ='Data Sheet'!F48 -> 5539.32 | G11: ='Data Sheet'!G48 -> 5340.98 | H11: ='Data Sheet'!H48 -> 5632.76 | I11: ='Data Sheet'!I48 -> 6288.82 | ... K11: ='Data Sheet'!K48 -> 6295.12
A12: Net profit | B12: ='Data Sheet'!B49 -> 12370.38 | C12: ='Data Sheet'!C49 -> 16811.41 | D12: ='Data Sheet'!D49 -> 17257.87 | E12: ='Data Sheet'!E49 -> 17622.38 | F12: ='Data Sheet'!F49 -> 16474.85 | G12: ='Data Sheet'!G49 -> 17825.91 | H12: ='Data Sheet'!H49 -> 17656.61 | I12: ='Data Sheet'!I49 -> 18834.88 | ... K12: ='Data Sheet'!K49 -> 19610.67
A14: OPM | B14: =IF(B4>0,B6/B4,"") -> 0.63903691 | C14: =IF(C4>0,C6/C4,"") -> 0.39565733 | D14: =IF(D4>0,D6/D4,"") -> 0.35224695 | E14: =IF(E4>0,E6/E4,"") -> 0.2076597 | F14: =IF(F4>0,F6/F4,"") -> 0.39065683 | G14: =IF(G4>0,G6/G4,"") -> 0.37261409 | H14: =IF(H4>0,H6/H4,"") -> 0.51426732 | I14: =IF(I4>0,I6/I4,"") -> 0.45022444 | ... K14: =IF(K4>0,K6/K4,"") -> 0.48087267

Sheet Balance Sheet
A1: ='Profit & Loss'!A1 -> HDFC BANK LTD | E1: =UPDATE | J1: SCREENER.IN
A3: Narration | B3: ='Data Sheet'!B56 -> 42460 | C3: ='Data Sheet'!C56 -> 42825 | D3: ='Data Sheet'!D56 -> 43190 | E3: ='Data Sheet'!E56 -> 43555 | F3: ='Data Sheet'!F56 -> 43921 | G3: ='Data Sheet'!G56 -> 44286 | H3: ='Data Sheet'!H56 -> 44651 | I3: ='Data Sheet'!I56 -> 45016 | ... K3: ='Data Sheet'!K56 -> 45747
A4: Equity Share Capital | B4: ='Data Sheet'!B57 -> 505.64 | C4: ='Data Sheet'!C57 -> 512.51 | D4: ='Data Sheet'!D57 -> 519.02 | E4: ='Data Sheet'!E57 -> 544.66 | F4: ='Data Sheet'!F57 -> 548.33 | G4: ='Data Sheet'!G57 -> 551.28 | H4: ='Data Sheet'!H57 -> 554.55 | I4: ='Data Sheet'!I57 -> 557.97 | ... K4: ='Data Sheet'!K57 -> 765.22
A5: Reserves | B5: ='Data Sheet'!B58 -> 73798.49 | C5: ='Data Sheet'!C58 -> 91281.44 | D5: ='Data Sheet'!D58 -> 109080.11 | E5: ='Data Sheet'!E58 -> 153128 | F5: ='Data Sheet'!F58 -> 175810.38 | G5: ='Data Sheet'!G58 -> 209258.9 | H5: ='Data Sheet'!H58 -> 246771.62 | I5: ='Data Sheet'!I58 -> 288879.53 | ... K5: ='Data Sheet'!K58 -> 521024.17
A6: Borrowings | B6: ='Data Sheet'!B59 -> 649587.25 | C6: ='Data Sheet'!C59 -> 741549.89 | D6: ='Data Sheet'!D59 -> 944817.22 | E6: ='Data Sheet'!E59 -> 1080235.5 | F6: ='Data Sheet'!F59 -> 1333041.4 | G6: ='Data Sheet'!G59 -> 1511417.6 | H6: ='Data Sheet'!H59 -> 1784969.5 | I6: ='Data Sheet'!I59 -> 2139211.9 | ... K6: ='Data Sheet'!K59 -> 3345503.8
A7: Other Liabilities | B7: ='Data Sheet'!B60 -> 38320.95 | C7: ='Data Sheet'!C60 -> 59000.32 | D7: ='Data Sheet'!D60 -> 48769.82 | E7: ='Data Sheet'!E60 -> 58897.59 | F7: ='Data Sheet'!F60 -> 71430.27 | G7: ='Data Sheet'!G60 -> 78278.83 | H7: ='Data Sheet'!H60 -> 90638.6 | I7: ='Data Sheet'!I60 -> 101783.03 | ... K7: ='Data Sheet'!K60 -> 524816.64
A8: Total | B8: ='Data Sheet'!B61 -> 762212.33 | C8: ='Data Sheet'!C61 -> 892344.16 | D8: ='Data Sheet'!D61 -> 1103186.2 | E8: ='Data Sheet'!E61 -> 1292805.7 | F8: ='Data Sheet'!F61 -> 1580830.4 | G8: ='Data Sheet'!G61 -> 1799506.6 | H8: ='Data Sheet'!H61 -> 2122934.3 | I8: ='Data Sheet'!I61 -> 2530432.4 | ... K8: ='Data Sheet'!K61 -> 4392109.8
A10: Net Block | B10: ='Data Sheet'!B62 -> 3666.86 | C10: ='Data Sheet'!C62 -> 3999.7 | D10: ='Data Sheet'!D62 -> 4008.13 | E10: ='Data Sheet'!E62 -> 4368.63 | F10: ='Data Sheet'!F62 -> 4775.65 | G10: ='Data Sheet'!G62 -> 5248.35 | H10: ='Data Sheet'!H62 -> 6432.07 | I10: ='Data Sheet'!I62 -> 8431.35 | ... K10: ='Data Sheet'!K62 -> 15257.94
A11: Capital Work in Progress | B11: ='Data Sheet'!B63 -> 0 | C11: ='Data Sheet'!C63 -> 0 | D11: ='Data Sheet'!D63 -> 0 | E11: ='Data Sheet'!E63 -> 0 | F11: ='Data Sheet'!F63 -> 0 | G11: ='Data Sheet'!G63 -> 0 | H11: ='Data Sheet'!H63 -> 0 | I11: ='Data Sheet'!I63 -> 0 | ... K11: ='Data Sheet'!K63 -> 0
A12: Investments | B12: ='Data Sheet'!B64 -> 193633.85 | C12: ='Data Sheet'!C64 -> 210777.11 | D12: ='Data Sheet'!D64 -> 238460.92 | E12: ='Data Sheet'!E64 -> 289445.87 | F12: ='Data Sheet'!F64 -> 389304.95 | G12: ='Data Sheet'!G64 -> 438823.11 | H12: ='Data Sheet'!H64 -> 449263.86 | I12: ='Data Sheet'!I64 -> 511581.71 | ... K12: ='Data Sheet'!K64 -> 1186472.9
A13: Other Assets | B13: ='Data Sheet'!B65 -> 564911.62 | C13: ='Data Sheet'!C65 -> 677567.35 | D13: ='Data Sheet'!D65 -> 860717.12 | E13: ='Data Sheet'!E65 -> 998991.21 | F13: ='Data Sheet'!F65 -> 1186749.8 | G13: ='Data Sheet'!G65 -> 1355435.2 | H13: ='Data Sheet'!H65 -> 1667238.4 | I13: ='Data Sheet'!I65 -> 2010419.4 | ... K13: ='Data Sheet'!K65 -> 3190379
A14: Total | B14: ='Data Sheet'!B66 -> 762212.33 | C14: ='Data Sheet'!C66 -> 892344.16 | D14: ='Data Sheet'!D66 -> 1103186.2 | E14: ='Data Sheet'!E66 -> 1292805.7 | F14: ='Data Sheet'!F66 -> 1580830.4 | G14: ='Data Sheet'!G66 -> 1799506.6 | H14: ='Data Sheet'!H66 -> 2122934.3 | I14: ='Data Sheet'!I66 -> 2530432.4 | ... K14: ='Data Sheet'!K66 -> 4392109.8
A16: Working Capital | B16: =B13-B7 -> 526590.67 | C16: =C13-C7 -> 618567.03 | D16: =D13-D7 -> 811947.3 | E16: =E13-E7 -> 940093.62 | F16: =F13-F7 -> 1115319.6 | G16: =G13-G7 -> 1277156.3 | H16: =H13-H7 -> 1576599.8 | I16: =I13-I7 -> 1908636.3 | ... K16: =K13-K7 -> 2665562.4
A17: Debtors | B17: ='Data Sheet'!B67 -> 0 | C17: ='Data Sheet'!C67 -> 0 | D17: ='Data Sheet'!D67 -> 0 | E17: ='Data Sheet'!E67 -> 0 | F17: ='Data Sheet'!F67 -> 0 | G17: ='Data Sheet'!G67 -> 0 | H17: ='Data Sheet'!H67 -> 0 | I17: ='Data Sheet'!I67 -> 0 | ... K17: ='Data Sheet'!K67 -> 0
A18: Inventory | B18: ='Data Sheet'!B68 -> 0 | C18: ='Data Sheet'!C68 -> 0 | D18: ='Data Sheet'!D68 -> 0 | E18: ='Data Sheet'!E68 -> 0 | F18: ='Data Sheet'!F68 -> 0 | G18: ='Data Sheet'!G68 -> 0 | H18: ='Data Sheet'!H68 -> 0 | I18: ='Data Sheet'!I68 -> 0 | ... K18: ='Data Sheet'!K68 -> 0
A20: Debtor Days | B20: =IF('Profit & Loss'!B4>0,'Balance Sheet'!B17/('Profit & Loss'!B4/365),0) -> 0 | C20: =IF('Profit & Loss'!C4>0,'Balance Sheet'!C17/('Profit & Loss'!C4/365),0) -> 0 | D20: =IF('Profit & Loss'!D4>0,'Balance Sheet'!D17/('Profit & Loss'!D4/365),0) -> 0 | E20: =IF('Profit & Loss'!E4>0,'Balance Sheet'!E17/('Profit & Loss'!E4/365),0) -> 0 | F20: =IF('Profit & Loss'!F4>0,'Balance Sheet'!F17/('Profit & Loss'!F4/365),0) -> 0 | G20: =IF('Profit & Loss'!G4>0,'Balance Sheet'!G17/('Profit & Loss'!G4/365),0) -> 0 | H20: =IF('Profit & Loss'!H4>0,'Balance Sheet'!H17/('Profit & Loss'!H4/365),0) -> 0 | I20: =IF('Profit & Loss'!I4>0,'Balance Sheet'!I17/('Profit & Loss'!I4/365),0) -> 0 | ... K20: =IF('Profit & Loss'!K4>0,'Balance Sheet'!K17/('Profit & Loss'!K4/365),0) -> 0
A21: Inventory Turnover | B21: =IF('Balance Sheet'!B18>0,'Profit & Loss'!B4/'Balance Sheet'!B18,0) -> 0 | C21: =IF('Balance Sheet'!C18>0,'Profit & Loss'!C4/'Balance Sheet'!C18,0) -> 0 | D21: =IF('Balance Sheet'!D18>0,'Profit & Loss'!D4/'Balance Sheet'!D18,0) -> 0 | E21: =IF('Balance Sheet'!E18>0,'Profit & Loss'!E4/'Balance Sheet'!E18,0) -> 0 | F21: =IF('Balance Sheet'!F18>0,'Profit & Loss'!F4/'Balance Sheet'!F18,0) -> 0 | G21: =IF('Balance Sheet'!G18>0,'Profit & Loss'!G4/'Balance Sheet'!G18,0) -> 0 | H21: =IF('Balance Sheet'!H18>0,'Profit & Loss'!H4/'Balance Sheet'!H18,0) -> 0 | I21: =IF('Balance Sheet'!I18>0,'Profit & Loss'!I4/'Balance Sheet'!I18,0) -> 0 | ... K21: =IF('Balance Sheet'!K18>0,'Profit & Loss'!K4/'Balance Sheet'!K18,0) -> 0
A23: Return on Equity | B23: =IF(SUM('Balance Sheet'!B4:B5)>0,'Profit & Loss'!B12/SUM('Balance Sheet'!B4:B5),"") -> 0.17228289 | C23: =IF(SUM('Balance Sheet'!C4:C5)>0,'Profit & Loss'!C12/SUM('Balance Sheet'!C4:C5),"") -> 0.166465 | D23: =IF(SUM('Balance Sheet'!D4:D5)>0,'Profit & Loss'!D12/SUM('Balance Sheet'!D4:D5),"") -> 0.16888838 | E23: =IF(SUM('Balance Sheet'!E4:E5)>0,'Profit & Loss'!E12/SUM('Balance Sheet'!E4:E5),"") -> 0.14532468 | F23: =IF(SUM('Balance Sheet'!F4:F5)>0,'Profit & Loss'!F12/SUM('Balance Sheet'!F4:F5),"") -> 0.15453702 | G23: =IF(SUM('Balance Sheet'!G4:G5)>0,'Profit & Loss'!G12/SUM('Balance Sheet'!G4:G5),"") -> 0.15172386 | H23: =IF(SUM('Balance Sheet'!H4:H5)>0,'Profit & Loss'!H12/SUM('Balance Sheet'!H4:H5),"") -> 0.15385654 | I23: =IF(SUM('Balance Sheet'!I4:I5)>0,'Profit & Loss'!I12/SUM('Balance Sheet'!I4:I5),"") -> 0.15891897 | ... K23: =IF(SUM('Balance Sheet'!K4:K5)>0,'Profit & Loss'!K12/SUM('Balance Sheet'!K4:K5),"") -> 0.13567208
A24: Return on Capital Emp | C24: =IF((B4+B5+B6+C4+C5+C6)>0,('Profit & Loss'!C10+'Profit & Loss'!C9)*2/(B4+B5+B6+C4+C5+C6),"") -> 0.078902081 | D24: =IF((C4+C5+C6+D4+D5+D6)>0,('Profit & Loss'!D10+'Profit & Loss'!D9)*2/(C4+C5+C6+D4+D5+D6),"") -> 0.075057627 | E24: =IF((D4+D5+D6+E4+E5+E6)>0,('Profit & Loss'!E10+'Profit & Loss'!E9)*2/(D4+D5+D6+E4+E5+E6),"") -> 0.076939133 | F24: =IF((E4+E5+E6+F4+F5+F6)>0,('Profit & Loss'!F10+'Profit & Loss'!F9)*2/(E4+E5+E6+F4+F5+F6),"") -> 0.073146923 | G24: =IF((F4+F5+F6+G4+G5+G6)>0,('Profit & Loss'!G10+'Profit & Loss'!G9)*2/(F4+F5+F6+G4+G5+G6),"") -> 0.063172697 | H24: =IF((G4+G5+G6+H4+H5+H6)>0,('Profit & Loss'!H10+'Profit & Loss'!H9)*2/(G4+G5+G6+H4+H5+H6),"") -> 0.058322645 | I24: =IF((H4+H5+H6+I4+I5+I6)>0,('Profit & Loss'!I10+'Profit & Loss'!I9)*2/(H4+H5+H6+I4+I5+I6),"") -> 0.062443418 | J24: =IF((I4+I5+I6+J4+J5+J6)>0,('Profit & Loss'!J10+'Profit & Loss'!J9)*2/(I4+I5+I6+J4+J5+J6),"") -> 0.076998023 | K24: =IF((J4+J5+J6+K4+K5+K6)>0,('Profit & Loss'!K10+'Profit & Loss'!K9)*2/(J4+J5+J6+K4+K5+K6),"") -> 0.075394709

Sheet Cash Flow
A1: ='Balance Sheet'!A1 -> HDFC BANK LTD | E1: =UPDATE | J1: SCREENER.IN
A3: Narration | B3: ='Data Sheet'!B81 -> 42460 | C3: ='Data Sheet'!C81 -> 42825 | D3: ='Data Sheet'!D81 -> 43190 | E3: ='Data Sheet'!E81 -> 43555 | F3: ='Data Sheet'!F81 -> 43921 | G3: ='Data Sheet'!G81 -> 44286 | H3: ='Data Sheet'!H81 -> 44651 | I3: ='Data Sheet'!I81 -> 45016 | ... K3: ='Data Sheet'!K81 -> 45747
A4: Cash from Operating Activity | B4: ='Data Sheet'!B82 -> -34435.37 | C4: ='Data Sheet'!C82 -> 17281.59 | D4: ='Data Sheet'!D82 -> 17214.38 | E4: ='Data Sheet'!E82 -> -62871.54 | F4: ='Data Sheet'!F82 -> -16869.09 | G4: ='Data Sheet'!G82 -> 42476.45 | H4: ='Data Sheet'!H82 -> -11959.57 | I4: ='Data Sheet'!I82 -> 20813.7 | ... K4: ='Data Sheet'!K82 -> 127241.84
A5: Cash from Investing Activity | B5: ='Data Sheet'!B83 -> -837.31 | C5: ='Data Sheet'!C83 -> -1146.38 | D5: ='Data Sheet'!D83 -> -841.6 | E5: ='Data Sheet'!E83 -> -1503.06 | F5: ='Data Sheet'!F83 -> -1402.94 | G5: ='Data Sheet'!G83 -> -1822.7 | H5: ='Data Sheet'!H83 -> -2051.23 | I5: ='Data Sheet'!I83 -> -2992.18 | ... K5: ='Data Sheet'!K83 -> -3650.91
A6: Cash from Financing Activity | B6: ='Data Sheet'!B84 -> 37815.13 | C6: ='Data Sheet'!C84 -> -5892.97 | D6: ='Data Sheet'!D84 -> 57377.66 | E6: ='Data Sheet'!E84 -> 23130.69 | F6: ='Data Sheet'!F84 -> 24394.5 | G6: ='Data Sheet'!G84 -> -7321.35 | H6: ='Data Sheet'!H84 -> 48124.02 | I6: ='Data Sheet'!I84 -> 23940.56 | ... K6: ='Data Sheet'!K84 -> -102477.54
A7: Net Cash Flow | B7: ='Data Sheet'!B85 -> 2542.46 | C7: ='Data Sheet'!C85 -> 10242.24 | D7: ='Data Sheet'!D85 -> 73750.44 | E7: ='Data Sheet'!E85 -> -41243.91 | F7: ='Data Sheet'!F85 -> 6122.47 | G7: ='Data Sheet'!G85 -> 33332.4 | H7: ='Data Sheet'!H85 -> 34113.22 | I7: ='Data Sheet'!I85 -> 41762.08 | ... K7: ='Data Sheet'!K85 -> 21113.39

Sheet Customization
A1: How to use it?
A3: You can customize this workbook as you want.
B4: You can add custom formating, add conditional formating, add your own formulas… do ANYTHING.
B5: Please don't edit the "Data Sheet" only.
A7: After customization, you can upload this back on Screener.
B8: Upload on: | C8: https://www.screener.in/excel/
A10: Download your customized workbooks now onwards.
B11: Now whenever you will "Export to excel" from Screener, it will export your customized file.
A14: TESTING:
B15: This is a testing feature currently.
B16: You can report any formula errors on the worksheet at: support@screener.in

Sheet 3-Statement Model
B2: ="Historical & Forecasted Financial Statements - "& +'Data Sheet'!B1 -> Historical & Forecasted Financial Statements - HDFC BANK LTD
C3: Historic | H3: Forecast
B4: Years | C4: ='Data Sheet'!H56 -> 44651 | D4: ='Data Sheet'!I56 -> 45016 | E4: ='Data Sheet'!J56 -> 45382 | F4: ='Data Sheet'!K56 -> 45747 | H4: =F4+365 -> 46112 | I4: =H4+365 -> 46477 | J4: =I4+365 -> 46842 | K4: =J4+365 -> 47207 | L4: =K4+365 -> 47572
C5: 1 | D5: 2 | E5: 3 | F5: 4 | H5: 5 | I5: 6 | J5: 7 | K5: 8 | L5: 9
A6: # | B6: Income Statement
B7: I. INCOME
B8: Interest earned | C8: =IFERROR('P&L Raw Data'!C4/10000,0) -> 127753.12 | D8: =IFERROR('P&L Raw Data'!D4/10000,0) -> 161585.54 | E8: =IFERROR('P&L Raw Data'!E4/10000,0) -> 258340.58 | F8: =IFERROR('P&L Raw Data'!F4/10000,0) -> 300517.04 | H8: =FORECAST(H$5,$C8:$F8,$C$5:$F$5) -> 365810.77 | I8: =FORECAST(I$5,$C8:$F8,$C$5:$F$5) -> 427315.45 | J8: =FORECAST(J$5,$C8:$F8,$C$5:$F$5) -> 488820.13 | K8: =FORECAST(K$5,$C8:$F8,$C$5:$F$5) -> 550324.81 | L8: =FORECAST(L$5,$C8:$F8,$C$5:$F$5) -> 611829.49
B9: less: Interest expended1 | C9: =C16 -> 55743.528 | D9: =D16 -> 74743.317 | E9: =E16 -> 149808.1 | F9: =F16 -> 177846.95 | H9: =H16 -> 224879.24 | I9: =FORECAST(I$5,$C9:$F9,$C$5:$F$5) -> 269016.74 | J9: =FORECAST(J$5,$C9:$F9,$C$5:$F$5) -> 313154.25 | K9: =FORECAST(K$5,$C9:$F9,$C$5:$F$5) -> 357291.76 | L9: =FORECAST(L$5,$C9:$F9,$C$5:$F$5) -> 401429.26
B10: Net Interest Income(NII)2 | C10: =C8-C9 -> 72009.591 | D10: =D8-D9 -> 86842.219 | E10: =E8-E9 -> 108532.47 | F10: =F8-F9 -> 122670.09 | H10: =H8-H9 -> 140931.53 | I10: =I8-I9 -> 158298.71 | J10: =J8-J9 -> 175665.88 | K10: =K8-K9 -> 193033.06 | L10: =L8-L9 -> 210400.23
B11: Add: Other income3 | C11: =IFERROR('P&L Raw Data'!C5/10000,0) -> 29509.9 | D11: =IFERROR('P&L Raw Data'!D5/10000,0) -> 31214.825 | E11: =IFERROR('P&L Raw Data'!E5/10000,0) -> 49240.999 | F11: =IFERROR('P&L Raw Data'!F5/10000,0) -> 45632.282 | H11: =FORECAST(H$5,$C11:$F11,$C$5:$F$5) -> 55497.831 | I11: =FORECAST(I$5,$C11:$F11,$C$5:$F$5) -> 62137.163 | J11: =FORECAST(J$5,$C11:$F11,$C$5:$F$5) -> 68776.495 | K11: =FORECAST(K$5,$C11:$F11,$C$5:$F$5) -> 75415.827 | L11: =FORECAST(L$5,$C11:$F11,$C$5:$F$5) -> 82055.159
B12: Operating Income4 | C12: =SUM(C10:C11) -> 101519.49 | D12: =SUM(D10:D11) -> 118057.04 | E12: =SUM(E10:E11) -> 157773.47 | F12: =SUM(F10:F11) -> 168302.37 | H12: =FORECAST(H$5,$C12:$F12,$C$5:$F$5) -> 196429.36 | I12: =FORECAST(I$5,$C12:$F12,$C$5:$F$5) -> 220435.87 | J12: =FORECAST(J$5,$C12:$F12,$C$5:$F$5) -> 244442.38 | K12: =FORECAST(K$5,$C12:$F12,$C$5:$F$5) -> 268448.88 | L12: =FORECAST(L$5,$C12:$F12,$C$5:$F$5) -> 292455.39
B13: Total | C13: =SUM(C8,C11) -> 157263.02 | D13: =SUM(D8,D11) -> 192800.36 | E13: =SUM(E8,E11) -> 307581.57 | F13: =SUM(F8,F11) -> 346149.32 | H13: =SUM(H8,H11) -> 421308.6 | I13: =SUM(I8,I11) -> 489452.61 | J13: =SUM(J8,J11) -> 557596.63 | K13: =SUM(K8,K11) -> 625740.64 | L13: =SUM(L8,L11) -> 693884.65
B15: II. EXPENDITURE
B16: Interest expended | C16: =IFERROR('P&L Raw Data'!C8/10000,0) -> 55743.528 | D16: =IFERROR('P&L Raw Data'!D8/10000,0) -> 74743.317 | E16: =IFERROR('P&L Raw Data'!E8/10000,0) -> 149808.1 | F16: =IFERROR('P&L Raw Data'!F8/10000,0) -> 177846.95 | H16: =FORECAST(H$5,$C16:$F16,$C$5:$F$5) -> 224879.24 | I16: =FORECAST(I$5,$C16:$F16,$C$5:$F$5) -> 269016.74 | J16: =FORECAST(J$5,$C16:$F16,$C$5:$F$5) -> 313154.25 | K16: =FORECAST(K$5,$C16:$F16,$C$5:$F$5) -> 357291.76 | L16: =FORECAST(L$5,$C16:$F16,$C$5:$F$5) -> 401429.26
B17: Operating expenses | C17: =IFERROR('P&L Raw Data'!C9/10000,0) -> 37442.186 | D17: =IFERROR('P&L Raw Data'!D9/10000,0) -> 47652.084 | E17: =IFERROR('P&L Raw Data'!E9/10000,0) -> 63386.024 | F17: =IFERROR('P&L Raw Data'!F9/10000,0) -> 68174.882 | H17: =FORECAST(H$5,$C17:$F17,$C$5:$F$5) -> 81146.801 | I17: =FORECAST(I$5,$C17:$F17,$C$5:$F$5) -> 91940.004 | J17: =FORECAST(J$5,$C17:$F17,$C$5:$F$5) -> 102733.21 | K17: =FORECAST(K$5,$C17:$F17,$C$5:$F$5) -> 113526.41 | L17: =FORECAST(L$5,$C17:$F17,$C$5:$F$5) -> 124319.61
B18: Provisions and contingencies | C18: =IFERROR('P&L Raw Data'!C10/10000,0) -> 27115.95 | D18: =IFERROR('P&L Raw Data'!D10/10000,0) -> 26296.259 | E18: =IFERROR('P&L Raw Data'!E10/10000,0) -> 33575.172 | F18: =IFERROR('P&L Raw Data'!F10/10000,0) -> 32780.131 | H18: =FORECAST(H$5,$C18:$F18,$C$5:$F$5) -> 36009.741 | I18: =FORECAST(I$5,$C18:$F18,$C$5:$F$5) -> 38436.887 | J18: =FORECAST(J$5,$C18:$F18,$C$5:$F$5) -> 40864.032 | K18: =FORECAST(K$5,$C18:$F18,$C$5:$F$5) -> 43291.178 | L18: =FORECAST(L$5,$C18:$F18,$C$5:$F$5) -> 45718.323
B19: Total | C19: =SUM(C16:C18) -> 120301.66 | D19: =SUM(D16:D18) -> 148691.66 | E19: =SUM(E16:E18) -> 246769.3 | F19: =SUM(F16:F18) -> 278801.97 | H19: =FORECAST(H$5,$C19:$F19,$C$5:$F$5) -> 342035.78 | I19: =FORECAST(I$5,$C19:$F19,$C$5:$F$5) -> 399393.64 | J19: =FORECAST(J$5,$C19:$F19,$C$5:$F$5) -> 456751.49 | K19: =FORECAST(K$5,$C19:$F19,$C$5:$F$5) -> 514109.34 | L19: =FORECAST(L$5,$C19:$F19,$C$5:$F$5) -> 571467.2
B21: III. PROFIT
B22: Net profit for the year | C22: =IFERROR('P&L Raw Data'!C13/10000,0) -> 36961.355 | D22: =IFERROR('P&L Raw Data'!D13/10000,0) -> 44108.701 | E22: =IFERROR('P&L Raw Data'!E13/10000,0) -> 60812.279 | F22: =IFERROR('P&L Raw Data'!F13/10000,0) -> 67347.358 | H22: =FORECAST(H$5,$C22:$F22,$C$5:$F$5) -> 79272.82 | I22: =FORECAST(I$5,$C22:$F22,$C$5:$F$5) -> 90058.978 | J22: =FORECAST(J$5,$C22:$F22,$C$5:$F$5) -> 100845.14 | K22: =FORECAST(K$5,$C22:$F22,$C$5:$F$5) -> 111631.3 | L22: =FORECAST(L$5,$C22:$F22,$C$5:$F$5) -> 122417.45
B23: Balance in the Profit and Loss account brought forward | C23: =IFERROR('P&L Raw Data'!C14/10000,0) -> 73652.795 | D23: =IFERROR('P&L Raw Data'!D14/10000,0) -> 93185.674 | E23: =IFERROR('P&L Raw Data'!E14/10000,0) -> 112960 | F23: =IFERROR('P&L Raw Data'!F14/10000,0) -> 139579.83 | H23: =FORECAST(H$5,$C23:$F23,$C$5:$F$5) -> 159233.43 | I23: =FORECAST(I$5,$C23:$F23,$C$5:$F$5) -> 180988.97 | J23: =FORECAST(J$5,$C23:$F23,$C$5:$F$5) -> 202744.52 | K23: =FORECAST(K$5,$C23:$F23,$C$5:$F$5) -> 224500.06 | L23: =FORECAST(L$5,$C23:$F23,$C$5:$F$5) -> 246255.6
B24: Additions on Amalgamation (net) | C24: =IFERROR('P&L Raw Data'!C15/10000,0) -> 0 | D24: =IFERROR('P&L Raw Data'!D15/10000,0) -> 0 | E24: =IFERROR('P&L Raw Data'!E15/10000,0) -> 3570.1097 | F24: =IFERROR('P&L Raw Data'!F15/10000,0) -> 0 | H24: =IFERROR('P&L Raw Data'!G15/10000,0) -> 0 | I24: =IFERROR('P&L Raw Data'!H15/10000,0) -> 0 | J24: =IFERROR('P&L Raw Data'!I15/10000,0) -> 0 | K24: =IFERROR('P&L Raw Data'!J15/10000,0) -> 0 | L24: =IFERROR('P&L Raw Data'!K15/10000,0) -> 0
B25: Total | C25: =SUM(C22:C24) -> 110614.15 | D25: =SUM(D22:D24) -> 137294.38 | E25: =SUM(E22:E24) -> 177342.38 | F25: =SUM(F22:F24) -> 206927.19 | H25: =FORECAST(H$5,$C25:$F25,$C$5:$F$5) -> 240291.31 | I25: =FORECAST(I$5,$C25:$F25,$C$5:$F$5) -> 273190.02 | J25: =FORECAST(J$5,$C25:$F25,$C$5:$F$5) -> 306088.73 | K25: =FORECAST(K$5,$C25:$F25,$C$5:$F$5) -> 338987.44 | L25: =FORECAST(L$5,$C25:$F25,$C$5:$F$5) -> 371886.16
B27: IV. EARNINGS PER EQUITY SHARE
B28: Weighted average number of equity shares(Basic EPS) | C28: =IFERROR(Assumptions!C30/10000000,0) -> 553.32036 | D28: =IFERROR(Assumptions!D30/10000000,0) -> 556.57143 | E28: =IFERROR(Assumptions!E30/10000000,0) -> 708.48074 | F28: =IFERROR(Assumptions!F30/10000000,0) -> 762.77932 | H28: =FORECAST(H$5,$C28:$F28,$C$5:$F$5) -> 840.35951 | I28: =FORECAST(I$5,$C28:$F28,$C$5:$F$5) -> 918.38813 | J28: =FORECAST(J$5,$C28:$F28,$C$5:$F$5) -> 996.41675 | K28: =FORECAST(K$5,$C28:$F28,$C$5:$F$5) -> 1074.4454 | L28: =FORECAST(L$5,$C28:$F28,$C$5:$F$5) -> 1152.474
B29: Weighted average number of equity shares(Diluted EPS) | C29: =IFERROR(Assumptions!C32/10000000,0) -> 557.0934 | D29: =IFERROR(Assumptions!D32/10000000,0) -> 559.11837 | E29: =IFERROR(Assumptions!E32/10000000,0) -> 711.72532 | F29: =IFERROR(Assumptions!F32/10000000,0) -> 766.19706 | H29: =FORECAST(H$5,$C29:$F29,$C$5:$F$5) -> 843.51302 | I29: =FORECAST(I$5,$C29:$F29,$C$5:$F$5) -> 921.50481 | J29: =FORECAST(J$5,$C29:$F29,$C$5:$F$5) -> 999.4966 | K29: =FORECAST(K$5,$C29:$F29,$C$5:$F$5) -> 1077.4884 | L29: =FORECAST(L$5,$C29:$F29,$C$5:$F$5) -> 1155.4802
B30: Basic | C30: =IFERROR(C$22/C28,0) -> 66.799196 | D30: =IFERROR(D$22/D28,0) -> 79.250747 | E30: =IFERROR(E$22/E28,0) -> 85.834765 | F30: =IFERROR(F$22/F28,0) -> 88.292061 | H30: =FORECAST(H$5,$C30:$F30,$C$5:$F$5) -> 97.809846 | I30: =FORECAST(I$5,$C30:$F30,$C$5:$F$5) -> 104.91611 | J30: =FORECAST(J$5,$C30:$F30,$C$5:$F$5) -> 112.02237 | K30: =FORECAST(K$5,$C30:$F30,$C$5:$F$5) -> 119.12863 | L30: =FORECAST(L$5,$C30:$F30,$C$5:$F$5) -> 126.23489
B31: Diluted | C31: =IFERROR(C$22/C29,0) -> 66.346784 | D31: =IFERROR(D$22/D29,0) -> 78.889738 | E31: =IFERROR(E$22/E29,0) -> 85.443467 | F31: =IFERROR(F$22/F29,0) -> 87.898221 | H31: =FORECAST(H$5,$C31:$F31,$C$5:$F$5) -> 97.446562 | I31: =FORECAST(I$5,$C31:$F31,$C$5:$F$5) -> 104.56737 | J31: =FORECAST(J$5,$C31:$F31,$C$5:$F$5) -> 111.68817 | K31: =FORECAST(K$5,$C31:$F31,$C$5:$F$5) -> 118.80897 | L31: =FORECAST(L$5,$C31:$F31,$C$5:$F$5) -> 125.92978
A34: # | B34: Balance Sheet
B35: CAPITAL AND LIABILITIES
B36: Capital | C36: =IFERROR('Balance Sheet Raw Data'!C4/10000,0) -> 554.5541 | D36: =IFERROR('Balance Sheet Raw Data'!D4/10000,0) -> 557.9743 | E36: =IFERROR('Balance Sheet Raw Data'!E4/10000,0) -> 759.6911 | F36: =IFERROR('Balance Sheet Raw Data'!F4/10000,0) -> 765.2222 | H36: =FORECAST(H$5,$C36:$F36,$C$5:$F$5) -> 867.7907 | I36: =FORECAST(I$5,$C36:$F36,$C$5:$F$5) -> 951.16281 | J36: =FORECAST(J$5,$C36:$F36,$C$5:$F$5) -> 1034.5349 | K36: =FORECAST(K$5,$C36:$F36,$C$5:$F$5) -> 1117.907 | L36: =FORECAST(L$5,$C36:$F36,$C$5:$F$5) -> 1201.2791
B37: Reserves and surplus | C37: =IFERROR(SUM('Balance Sheet Raw Data'!C5:C6)/10000,0) -> 239538.38 | D37: =IFERROR(SUM('Balance Sheet Raw Data'!D5:D6)/10000,0) -> 279641.03 | E37: =IFERROR(SUM('Balance Sheet Raw Data'!E5:E6)/10000,0) -> 439486.11 | F37: =IFERROR(SUM('Balance Sheet Raw Data'!F5:F6)/10000,0) -> 500659.42 | H37: =FORECAST(H$5,$C37:$F37,$C$5:$F$5) -> 600633.28 | I37: =FORECAST(I$5,$C37:$F37,$C$5:$F$5) -> 694954.1 | J37: =FORECAST(J$5,$C37:$F37,$C$5:$F$5) -> 789274.92 | K37: =FORECAST(K$5,$C37:$F37,$C$5:$F$5) -> 883595.74 | L37: =FORECAST(L$5,$C37:$F37,$C$5:$F$5) -> 977916.55
B38: Shareholer's Fund | C38: =SUM(C36:C37) -> 240092.94 | D38: =SUM(D36:D37) -> 280199.01 | E38: =SUM(E36:E37) -> 440245.81 | F38: =SUM(F36:F37) -> 501424.64 | H38: =SUM(H36:H37) -> 601501.07 | I38: =SUM(I36:I37) -> 695905.26 | J38: =SUM(J36:J37) -> 790309.45 | K38: =SUM(K36:K37) -> 884713.64 | L38: =SUM(L36:L37) -> 979117.83
B39: Deposits | C39: =IFERROR('Balance Sheet Raw Data'!C7/10000,0) -> 1559217.4 | D39: =IFERROR('Balance Sheet Raw Data'!D7/10000,0) -> 1883394.6 | E39: =IFERROR('Balance Sheet Raw Data'!E7/10000,0) -> 2379786.3 | F39: =IFERROR('Balance Sheet Raw Data'!F7/10000,0) -> 2714714.9 | H39: =FORECAST(H$5,$C39:$F39,$C$5:$F$5) -> 3124999.3 | I39: =FORECAST(I$5,$C39:$F39,$C$5:$F$5) -> 3521287.7 | J39: =FORECAST(J$5,$C39:$F39,$C$5:$F$5) -> 3917576.1 | K39: =FORECAST(K$5,$C39:$F39,$C$5:$F$5) -> 4313864.5 | L39: =FORECAST(L$5,$C39:$F39,$C$5:$F$5) -> 4710152.9
B40: Borrowings | C40: =IFERROR('Balance Sheet Raw Data'!C8/10000,0) -> 184817.21 | D40: =IFERROR('Balance Sheet Raw Data'!D8/10000,0) -> 206765.57 | E40: =IFERROR('Balance Sheet Raw Data'!E8/10000,0) -> 662153.08 | F40: =IFERROR('Balance Sheet Raw Data'!F8/10000,0) -> 547930.89 | H40: =FORECAST(H$5,$C40:$F40,$C$5:$F$5) -> 786598.83 | I40: =FORECAST(I$5,$C40:$F40,$C$5:$F$5) -> 941071.68 | J40: =FORECAST(J$5,$C40:$F40,$C$5:$F$5) -> 1095544.5 | K40: =FORECAST(K$5,$C40:$F40,$C$5:$F$5) -> 1250017.4 | L40: =FORECAST(L$5,$C40:$F40,$C$5:$F$5) -> 1404490.3
B41: Other liabilities and provisions | C41: =IFERROR('Balance Sheet Raw Data'!C9/10000,0) -> 84407.464 | D41: =IFERROR('Balance Sheet Raw Data'!D9/10000,0) -> 95722.248 | E41: =IFERROR('Balance Sheet Raw Data'!E9/10000,0) -> 135437.93 | F41: =IFERROR('Balance Sheet Raw Data'!F9/10000,0) -> 146128.52 | H41: =FORECAST(H$5,$C41:$F41,$C$5:$F$5) -> 171643.75 | I41: =FORECAST(I$5,$C41:$F41,$C$5:$F$5) -> 194131.63 | J41: =FORECAST(J$5,$C41:$F41,$C$5:$F$5) -> 216619.52 | K41: =FORECAST(K$5,$C41:$F41,$C$5:$F$5) -> 239107.4 | L41: =FORECAST(L$5,$C41:$F41,$C$5:$F$5) -> 261595.29
B42: Total Liabilities | C42: =SUM(C38:C41) -> 2068535.1 | D42: =SUM(D38:D41) -> 2466081.5 | E42: =SUM(E38:E41) -> 3617623.1 | F42: =SUM(F38:F41) -> 3910198.9 | H42: =SUM(H38:H41) -> 4684743 | I42: =SUM(I38:I41) -> 5352396.3 | J42: =SUM(J38:J41) -> 6020049.6 | K42: =SUM(K38:K41) -> 6687703 | L42: =SUM(L38:L41) -> 7355356.3
B44: ASSETS
B45: Cash and balances with Reserve Bank of India | C45: =IFERROR('Balance Sheet Raw Data'!C12/10000,0) -> 129995.64 | D45: =IFERROR('Balance Sheet Raw Data'!D12/10000,0) -> 117160.77 | E45: =IFERROR('Balance Sheet Raw Data'!E12/10000,0) -> 178683.22 | F45: =IFERROR('Balance Sheet Raw Data'!F12/10000,0) -> 144355.03 | H45: =FORECAST(H$5,$C45:$F45,$C$5:$F$5) -> 168698.82 | I45: =FORECAST(I$5,$C45:$F45,$C$5:$F$5) -> 179158.89 | J45: =FORECAST(J$5,$C45:$F45,$C$5:$F$5) -> 189618.95 | K45: =FORECAST(K$5,$C45:$F45,$C$5:$F$5) -> 200079.01 | L45: =FORECAST(L$5,$C45:$F45,$C$5:$F$5) -> 210539.08
B46: Balances with banks and money at call and short notice | C46: =IFERROR('Balance Sheet Raw Data'!C13/10000,0) -> 22331.289 | D46: =IFERROR('Balance Sheet Raw Data'!D13/10000,0) -> 76604.312 | E46: =IFERROR('Balance Sheet Raw Data'!E13/10000,0) -> 40464.195 | F46: =IFERROR('Balance Sheet Raw Data'!F13/10000,0) -> 95215.642 | H46: =FORECAST(H$5,$C46:$F46,$C$5:$F$5) -> 104282.09 | I46: =FORECAST(I$5,$C46:$F46,$C$5:$F$5) -> 122533.39 | J46: =FORECAST(J$5,$C46:$F46,$C$5:$F$5) -> 140784.68 | K46: =FORECAST(K$5,$C46:$F46,$C$5:$F$5) -> 159035.98 | L46: =FORECAST(L$5,$C46:$F46,$C$5:$F$5) -> 177287.27
B47: Investments | C47: =IFERROR('Balance Sheet Raw Data'!C14/10000,0) -> 455535.69 | D47: =IFERROR('Balance Sheet Raw Data'!D14/10000,0) -> 517001.43 | E47: =IFERROR('Balance Sheet Raw Data'!E14/10000,0) -> 702414.96 | F47: =IFERROR('Balance Sheet Raw Data'!F14/10000,0) -> 836359.67 | H47: =FORECAST(H$5,$C47:$F47,$C$5:$F$5) -> 959799.31 | I47: =FORECAST(I$5,$C47:$F47,$C$5:$F$5) -> 1092587.9 | J47: =FORECAST(J$5,$C47:$F47,$C$5:$F$5) -> 1225376.4 | K47: =FORECAST(K$5,$C47:$F47,$C$5:$F$5) -> 1358164.9 | L47: =FORECAST(L$5,$C47:$F47,$C$5:$F$5) -> 1490953.5
...

Sheet Ratio Analysis
B2: ="Ratio Analysis - "& +'Data Sheet'!B1 -> Ratio Analysis - HDFC BANK LTD
C3: Historic | H3: Forecast
B4: Years | C4: ='Data Sheet'!H56 -> 44651 | D4: ='Data Sheet'!I56 -> 45016 | E4: ='Data Sheet'!J56 -> 45382 | F4: ='Data Sheet'!K56 -> 45747 | H4: =F4+365 -> 46112 | I4: =H4+365 -> 46477 | J4: =I4+365 -> 46842 | K4: =J4+365 -> 47207 | L4: =K4+365 -> 47572
C5: 1 | D5: 2 | E5: 3 | F5: 4 | H5: 5 | I5: 6 | J5: 7 | K5: 8 | L5: 9
B6: I. Profitability Ratios
B7: Return on Equity (ROE) | C7: ='3-Statement Model'!C22/'3-Statement Model'!C38 -> 0.15394603 | D7: ='3-Statement Model'!D22/'3-Statement Model'!D38 -> 0.15741919 | E7: ='3-Statement Model'!E22/'3-Statement Model'!E38 -> 0.13813256 | F7: ='3-Statement Model'!F22/'3-Statement Model'!F38 -> 0.13431202 | H7: ='3-Statement Model'!H22/'3-Statement Model'!H38 -> 0.13179165 | I7: ='3-Statement Model'!I22/'3-Statement Model'!I38 -> 0.1294127 | J7: ='3-Statement Model'!J22/'3-Statement Model'!J38 -> 0.12760209 | K7: ='3-Statement Model'!K22/'3-Statement Model'!K38 -> 0.12617788 | L7: ='3-Statement Model'!L22/'3-Statement Model'!L38 -> 0.12502832
B8: Return on Assets (ROA) | C8: ='3-Statement Model'!C22/Assumptions!C47 -> 0.019374798 | D8: ='3-Statement Model'!D22/Assumptions!D47 -> 0.019454215 | E8: ='3-Statement Model'!E22/Assumptions!E47 -> 0.019991858 | F8: ='3-Statement Model'!F22/Assumptions!F47 -> 0.01789292 | H8: =_xlfn.FORECAST.LINEAR(H$5,$C8:$F8,$C$5:$F$5) -> 0.01820145 | I8: =_xlfn.FORECAST.LINEAR(I$5,$C8:$F8,$C$5:$F$5) -> 0.017810651 | J8: =_xlfn.FORECAST.LINEAR(J$5,$C8:$F8,$C$5:$F$5) -> 0.017419852 | K8: =_xlfn.FORECAST.LINEAR(K$5,$C8:$F8,$C$5:$F$5) -> 0.017029053 | L8: =_xlfn.FORECAST.LINEAR(L$5,$C8:$F8,$C$5:$F$5) -> 0.016638254
B9: Net Interest Margins (NIM) | C9: ='3-Statement Model'!C10/Assumptions!C42 -> 0.042347105 | D9: ='3-Statement Model'!D10/Assumptions!D42 -> 0.044060606 | E9: ='3-Statement Model'!E10/Assumptions!E42 -> 0.0409181 | F9: ='3-Statement Model'!F10/Assumptions!F42 -> 0.036930775 | H9: =_xlfn.FORECAST.LINEAR(H$5,$C9:$F9,$C$5:$F$5) -> 0.036216273 | I9: =_xlfn.FORECAST.LINEAR(I$5,$C9:$F9,$C$5:$F$5) -> 0.034277123 | J9: =_xlfn.FORECAST.LINEAR(J$5,$C9:$F9,$C$5:$F$5) -> 0.032337974 | K9: =_xlfn.FORECAST.LINEAR(K$5,$C9:$F9,$C$5:$F$5) -> 0.030398824 | L9: =_xlfn.FORECAST.LINEAR(L$5,$C9:$F9,$C$5:$F$5) -> 0.028459675
B11: II. Efficiency Ratios
B12: Cost-to-Income | C12: ='3-Statement Model'!C17/'3-Statement Model'!C12 -> 0.36881771 | D12: ='3-Statement Model'!D17/'3-Statement Model'!D12 -> 0.40363609 | E12: ='3-Statement Model'!E17/'3-Statement Model'!E12 -> 0.40175336 | F12: ='3-Statement Model'!F17/'3-Statement Model'!F12 -> 0.40507381 | H12: ='3-Statement Model'!H17/'3-Statement Model'!H12 -> 0.41310932 | I12: ='3-Statement Model'!I17/'3-Statement Model'!I12 -> 0.41708277 | J12: ='3-Statement Model'!J17/'3-Statement Model'!J12 -> 0.42027577 | K12: ='3-Statement Model'!K17/'3-Statement Model'!K12 -> 0.42289768 | L12: ='3-Statement Model'!L17/'3-Statement Model'!L12 -> 0.42508915
B14: III. Asset Quality Ratios
B15: Gross Non-Performing Assets (GNPA) | C15: =Assumptions!C53/'3-Statement Model'!C48 -> 0.011791871 | D15: =Assumptions!D53/'3-Statement Model'!D48 -> 0.011257771 | E15: =Assumptions!E53/'3-Statement Model'!E48 -> 0.012545295 | F15: =Assumptions!F53/'3-Statement Model'!F48 -> 0.013445764 | H15: =_xlfn.FORECAST.LINEAR(H$5,$C15:$F15,$C$5:$F$5) -> 0.013822476 | I15: =_xlfn.FORECAST.LINEAR(I$5,$C15:$F15,$C$5:$F$5) -> 0.014447396 | J15: =_xlfn.FORECAST.LINEAR(J$5,$C15:$F15,$C$5:$F$5) -> 0.015072317 | K15: =_xlfn.FORECAST.LINEAR(K$5,$C15:$F15,$C$5:$F$5) -> 0.015697237 | L15: =_xlfn.FORECAST.LINEAR(L$5,$C15:$F15,$C$5:$F$5) -> 0.016322157
B16: Net Non-Performing Assets (NNPA) | C16: =(Assumptions!C53-Assumptions!C54)/('3-Statement Model'!C48-Assumptions!C54) -> 0.0032478963 | D16: =(Assumptions!D53-Assumptions!D54)/('3-Statement Model'!D48-Assumptions!D54) -> 0.0027527461 | E16: =(Assumptions!E53-Assumptions!E54)/('3-Statement Model'!E48-Assumptions!E54) -> 0.0032869469 | F16: =(Assumptions!F53-Assumptions!F54)/('3-Statement Model'!F48-Assumptions!F54) -> 0.0043612136 | H16: =_xlfn.FORECAST.LINEAR(H$5,$C16:$F16,$C$5:$F$5) -> 0.0043807389 | I16: =_xlfn.FORECAST.LINEAR(I$5,$C16:$F16,$C$5:$F$5) -> 0.0047681541 | J16: =_xlfn.FORECAST.LINEAR(J$5,$C16:$F16,$C$5:$F$5) -> 0.0051555694 | K16: =_xlfn.FORECAST.LINEAR(K$5,$C16:$F16,$C$5:$F$5) -> 0.0055429846 | L16: =_xlfn.FORECAST.LINEAR(L$5,$C16:$F16,$C$5:$F$5) -> 0.0059303999
B17: Provision Coverage Ratio(PCR) | C17: =Assumptions!C54/Assumptions!C53 -> 0.72692578 | D17: =Assumptions!D54/Assumptions!D53 -> 0.75756575 | E17: =Assumptions!E54/Assumptions!E53 -> 0.74042739 | F17: =Assumptions!F54/Assumptions!F53 -> 0.67860359 | H17: =_xlfn.FORECAST.LINEAR(H$5,$C17:$F17,$C$5:$F$5) -> 0.68535439 | I17: =_xlfn.FORECAST.LINEAR(I$5,$C17:$F17,$C$5:$F$5) -> 0.6691439 | J17: =_xlfn.FORECAST.LINEAR(J$5,$C17:$F17,$C$5:$F$5) -> 0.65293341 | K17: =_xlfn.FORECAST.LINEAR(K$5,$C17:$F17,$C$5:$F$5) -> 0.63672291 | L17: =_xlfn.FORECAST.LINEAR(L$5,$C17:$F17,$C$5:$F$5) -> 0.62051242
B18: Credit Cost Ratio | C18: =Assumptions!C54/(SUM(Assumptions!C35,Assumptions!C39)/2) -> 0.0093804046 | D18: =Assumptions!D54/(SUM(Assumptions!D35,Assumptions!D39)/2) -> 0.0091941595 | E18: =Assumptions!E54/(SUM(Assumptions!E35,Assumptions!E39)/2) -> 0.011299414 | F18: =Assumptions!F54/(SUM(Assumptions!F35,Assumptions!F39)/2) -> 0.0093652071 | H18: =_xlfn.FORECAST.LINEAR(H$5,$C18:$F18,$C$5:$F$5) -> 0.010324712 | I18: =_xlfn.FORECAST.LINEAR(I$5,$C18:$F18,$C$5:$F$5) -> 0.010530678 | J18: =_xlfn.FORECAST.LINEAR(J$5,$C18:$F18,$C$5:$F$5) -> 0.010736644 | K18: =_xlfn.FORECAST.LINEAR(K$5,$C18:$F18,$C$5:$F$5) -> 0.01094261 | L18: =_xlfn.FORECAST.LINEAR(L$5,$C18:$F18,$C$5:$F$5) -> 0.011148576
B20: IV. Capital Adequacy Ratio
B21: Capital Adequacy Ratio (CAR) | C21: =Assumptions!C16 -> 0.1766 | D21: =Assumptions!D16 -> 0.1839 | E21: =Assumptions!E16 -> 0.1997 | F21: =Assumptions!F16 -> 0.19672023 | H21: =_xlfn.FORECAST.LINEAR(H$5,$C21:$F21,$C$5:$F$5) -> 0.20827023 | I21: =_xlfn.FORECAST.LINEAR(I$5,$C21:$F21,$C$5:$F$5) -> 0.21588631 | J21: =_xlfn.FORECAST.LINEAR(J$5,$C21:$F21,$C$5:$F$5) -> 0.22350238 | K21: =_xlfn.FORECAST.LINEAR(K$5,$C21:$F21,$C$5:$F$5) -> 0.23111845 | L21: =_xlfn.FORECAST.LINEAR(L$5,$C21:$F21,$C$5:$F$5) -> 0.23873452
B23: V. Liquidity and Funding Ratios
B24: Credit-Deposit Ratio | C24: ='3-Statement Model'!C48/'3-Statement Model'!C39 -> 0.8778897 | D24: ='3-Statement Model'!D48/'3-Statement Model'!D39 -> 0.84984095 | E24: ='3-Statement Model'!E48/'3-Statement Model'!E39 -> 1.0441532 | F24: ='3-Statement Model'!F48/'3-Statement Model'!F39 -> 0.96496638 | H24: ='3-Statement Model'!H48/'3-Statement Model'!H39 -> 1.0168415 | I24: ='3-Statement Model'!I48/'3-Statement Model'!I39 -> 1.0340799 | J24: ='3-Statement Model'!J48/'3-Statement Model'!J39 -> 1.0478307 | K24: ='3-Statement Model'!K48/'3-Statement Model'!K39 -> 1.0590552 | L24: ='3-Statement Model'!L48/'3-Statement Model'!L39 -> 1.0683909
B25: CASA Ratio | C25: =Assumptions!C23/Assumptions!C25 -> 0.48168339 | D25: =Assumptions!D23/Assumptions!D25 -> 0.44387345 | E25: =Assumptions!E23/Assumptions!E25 -> 0.38186748 | F25: =Assumptions!F23/Assumptions!F25 -> 0.34794086 | H25: =_xlfn.FORECAST.LINEAR(H$5,$C25:$F25,$C$5:$F$5) -> 0.29803291 | I25: =Assumptions!H23/Assumptions!H25 -> 0.35 | J25: =Assumptions!I23/Assumptions!I25 -> 0.36 | K25: =Assumptions!J23/Assumptions!J25 -> 0.37 | L25: =Assumptions!K23/Assumptions!K25 -> 0.39
B27: VI. Growth Ratios (% YoY)
B28: Advances | C28: - | D28: ='3-Statement Model'!D48/'3-Statement Model'!C48-1 -> 0.16931723 | E28: ='3-Statement Model'!E48/'3-Statement Model'!D48-1 -> 0.55246995 | F28: ='3-Statement Model'!F48/'3-Statement Model'!E48-1 -> 0.054227206 | H28: ='3-Statement Model'!H48/'3-Statement Model'!F48-1 -> 0.21301667 | I28: ='3-Statement Model'!I48/'3-Statement Model'!H48-1 -> 0.14591505 | J28: ='3-Statement Model'!J48/'3-Statement Model'!I48-1 -> 0.12733496 | K28: ='3-Statement Model'!K48/'3-Statement Model'!J48-1 -> 0.1129522 | L28: ='3-Statement Model'!L48/'3-Statement Model'!K48-1 -> 0.10148881
B29: Deposits | C29: - | D29: ='3-Statement Model'!D39/'3-Statement Model'!C39-1 -> 0.2079102 | E29: ='3-Statement Model'!E39/'3-Statement Model'!D39-1 -> 0.2635622 | F29: ='3-Statement Model'!F39/'3-Statement Model'!E39-1 -> 0.14073895 | H29: ='3-Statement Model'!H39/'3-Statement Model'!F39-1 -> 0.15113352 | I29: ='3-Statement Model'!I39/'3-Statement Model'!H39-1 -> 0.12681232 | J29: ='3-Statement Model'!J39/'3-Statement Model'!I39-1 -> 0.11254076 | K29: ='3-Statement Model'!K39/'3-Statement Model'!J39-1 -> 0.10115653 | L29: ='3-Statement Model'!L39/'3-Statement Model'!K39-1 -> 0.091863896
B30: NII | C30: - | D30: ='3-Statement Model'!D10/'3-Statement Model'!C10-1 -> 0.20598129 | E30: ='3-Statement Model'!E10/'3-Statement Model'!D10-1 -> 0.24976625 | F30: ='3-Statement Model'!F10/'3-Statement Model'!E10-1 -> 0.1302616 | H30: ='3-Statement Model'!H10/'3-Statement Model'!F10-1 -> 0.1488663 | I30: ='3-Statement Model'!I10/'3-Statement Model'!H10-1 -> 0.12323129 | J30: ='3-Statement Model'!J10/'3-Statement Model'!I10-1 -> 0.10971141 | K30: ='3-Statement Model'!K10/'3-Statement Model'!J10-1 -> 0.098864816 | L30: ='3-Statement Model'!L10/'3-Statement Model'!K10-1 -> 0.089969953
B31: PAT | C31: - | D31: ='3-Statement Model'!D22/'3-Statement Model'!C22-1 -> 0.19337349 | E31: ='3-Statement Model'!E22/'3-Statement Model'!D22-1 -> 0.3786912 | F31: ='3-Statement Model'!F22/'3-Statement Model'!E22-1 -> 0.10746316 | H31: ='3-Statement Model'!H22/'3-Statement Model'!F22-1 -> 0.17707393 | I31: ='3-Statement Model'!I22/'3-Statement Model'!H22-1 -> 0.13606377 | J31: ='3-Statement Model'!J22/'3-Statement Model'!I22-1 -> 0.11976772 | K31: ='3-Statement Model'!K22/'3-Statement Model'!J22-1 -> 0.10695765 | L31: ='3-Statement Model'!L22/'3-Statement Model'!K22-1 -> 0.096623071
B33: Notes:
B34: 1.Forecast ratios are based on stable funding mix assumptions and conservative asset quality normalization
B35: 2.CASA ratios in forecast years are management assumptions, not trend extrapolations
B36: 3.RWA assumed to grow in line with advances at X%
B37: 4. Excess capital assumed retained as management buffer

Sheet Comparable Company Analysis
B2: ="Relative Valuation - "& +'Data Sheet'!B1 -> Relative Valuation - HDFC BANK LTD
C3: Market Data | K3: Valuation
B4: Company Name | C4: Share Price | D4: Share Outstanding | E4: Market Capitalisation | F4: BVPS | G4: EPS | I4: Net Income | K4: P/E | L4: P/B
B5: HDFC BANK LTD | C5: 994.3 | D5: 1538.25 | E5: =C5*D5 -> 1529482 | F5: =F22 -> 504.29914 | G5: =G22 -> 88.292061 | I5: ='3-Statement Model'!F22 -> 67347.358 | K5: =C5/G22 -> 11.261488 | L5: =C5/F22 -> 1.9716472
B6: ICICI BANK LTD | C6: 1366 | D6: 715.02 | E6: =C6*D6 -> 976717.32 | F6: =F23 -> 439.01709 | G6: =G23 -> 74.91 | I6: 53300.25 | K6: =C6/G23 -> 18.235216 | L6: =C6/F23 -> 3.1114962
B7: KOTAK MAH BANK | C7: 2182.4 | D7: 198.91 | E7: =C7*D7 -> 434101.18 | F7: =F24 -> 791.76009 | G7: =G24 -> 93.42 | I7: 18574.23 | K7: =C7/G24 -> 23.361165 | L7: =C7/F24 -> 2.7563905
B8: AXIS BANK | C8: 1219.6 | D8: 310.42 | E8: =C8*D8 -> 378588.23 | F8: =F25 -> 603.16668 | G8: =G25 -> 83.87 | I8: 25988.99 | K8: =C8/G25 -> 14.541552 | L8: =C8/F25 -> 2.021995
B9: IDBI BANK | C9: 99.53 | D9: 1075.24 | E9: =C9*D9 -> 107018.64 | F9: =F26 -> 57.308136 | G9: =G26 -> 8.63 | I9: 9284.32 | K9: =C9/G26 -> 11.533024 | L9: =C9/F26 -> 1.7367517
B11: Mean | K11: =AVERAGE(K6:K9) -> 16.917739 | L11: =AVERAGE(L6:L9) -> 2.4066583
B12: Median | K12: =MEDIAN(K6:K9) -> 16.388384 | L12: =MEDIAN(L6:L9) -> 2.3891927
B14: HDFC BANK LTD | K14: P/E based | L14: P/B based
B15: Implied Share Price | K15: =K12*G5 -> 1446.9642 | L15: =L12*$F$5 -> 1204.8679
B16: Shares outstanding | K16: =$D$5 -> 1538.25 | L16: =$D$5 -> 1538.25
B17: Implied Market Value | K17: =K16*K15 -> 2225792.7 | L17: =L16*L15 -> 1853388
B20: Book Value Per Share Schedule
B21: Company Name | C21: Shares O/S | D21: Reserves | E21: Equity Capital | F21: BVPS | G21: EPS
B22: HDFC BANK LTD | C22: 994.3 | D22: ='3-Statement Model'!F37 -> 500659.42 | E22: ='3-Statement Model'!F36 -> 765.2222 | F22: =SUM(D22:E22)/C22 -> 504.29914 | G22: ='3-Statement Model'!F30 -> 88.292061
B23: ICICI BANK LTD | C23: 715.02 | D23: 312481 | E23: 1425 | F23: =SUM(D23:E23)/C23 -> 439.01709 | G23: 74.91
B24: KOTAK MAH BANK | C24: 198.91 | D24: 156495 | E24: 994 | F24: =SUM(D24:E24)/C24 -> 791.76009 | G24: 93.42
B25: AXIS BANK | C25: 310.42 | D25: 186616 | E25: 619 | F25: =SUM(D25:E25)/C25 -> 603.16668 | G25: 83.87
B26: IDBI BANK | C26: 1075.24 | D26: 50868 | E26: 10752 | F26: =SUM(D26:E26)/C26 -> 57.308136 | G26: 8.63
B30: 1.Valuation suggests modest upside on a P/B basis, while P/E indicates fair valuation, supporting a long-term hold to mild buy view.
B31: 2. HDFC Bank’s lower P/B relative to peers may reflect near-term growth moderation post-merger, despite strong profitability metrics
B33: Notes:
B34: 1. Valuation assumes peer comparability and does not factor in near-term macro or regulatory risks.
B35: 2. Median multiples used to calculate implied share price.
B36: 3. Given the balance-sheet–driven nature of banking valuations, greater weight is assigned to P/B, with P/E used as a corroborative check.

Sheet P&L Raw Data
C2: 44651 | D2: 45016 | E2: 45382 | F2: 45747
B3: I. INCOME
B4: Interest earned | C4: 1277531191 | D4: 1615855367 | E4: 2583405755 | F4: 3005170417
B5: Other income | C5: 295099004 | D5: 312148251 | E5: 492409994 | F5: 456322818
B6: Total | C6: 1572630195 | D6: 1928003618 | E6: 3075815749 | F6: 3461493235
B7: II. EXPENDITURE
B8: Interest expended | C8: 557435282 | D8: 747433173 | E8: 1498081008 | F8: 1778469527
B9: Operating expenses | C9: 374421858 | D9: 476520844 | E9: 633860240 | F9: 681748820
B10: Provisions and contingencies | C10: 271159503 | D10: 262962587 | E10: 335751716 | F10: 327801307
B11: Total | C11: 1203016643 | D11: 1486916604 | E11: 2467692964 | F11: 2788019654
B12: III. PROFIT
B13: Net profit for the year | C13: 369613552 | D13: 441087014 | E13: 608122785 | F13: 673473581
B14: Balance in the Profit and Loss account brought forward | C14: 736527947 | D14: 931856743 | E14: 1129599963 | F14: 1395798306
B15: Additions on Amalgamation (net) | E15: 35701097 | F15: -
B16: Total | C16: 1106141499 | D16: 1372943757 | E16: 1773423845 | F16: 2069271887
B17: IV. APPROPRIATIONS
B18: Transfer to Statutory Reserve | C18: 92403388 | D18: 110271754 | E18: 152030697 | F18: 168368395
B19: Transfer to General Reserve | C19: 36961355 | D19: 44108702 | E19: 60812279 | F19: 67347358
B20: Transfer to Special Reserve | D20: 5000000 | E20: 30000000 | F20: 32000000
B21: Transfer to Capital Reserve | C21: 6664722 | D21: 46127 | E21: 41664119 | F21: 5069983
B22: Transfer to / (from) Investment Reserve Account (net) | C22: 2331331 | D22: -2947976 | E22: 5294222 | F22: -
B23: Transfer to / (from) Investment Fluctuation Reserve | D23: 820000 | E23: 3780000 | F23: -
B24: Dividend pertaining to previous year paid during the year | C24: 35923960 | D24: 86045187 | E24: 84044222 | F24: 148261930
B25: Balance carried over to Balance Sheet | C25: 931856743 | D25: 1129599963 | E25: 1395798306 | F25: 1648224221
B26: Total | C26: 1106141499 | D26: 1372943757 | E26: 1773423845 | F26: 2069271887
B27: V. EARNINGS PER EQUITY SHARE (Face value ` 1/- per share) 18 (31) ` `
B28: Basic | C28: 66.8 | D28: 79.25 | E28: 85.83 | F28: 88.29
B29: Diluted | C29: 66.35 | D29: 78.89 | E29: 85.44 | F29: 87.9

Sheet Balance Sheet Raw Data
C2: 44651 | D2: 45016 | E2: 45382 | F2: 45747
B3: CAPITAL AND LIABILITIES
B4: Capital | C4: 5545541 | D4: 5579743 | E4: 7596911 | F4: 7652222
B5: Employees stock options outstanding | E5: 26527161 | F5: 38051944
B6: Reserves and surplus | C6: 2395383846 | D6: 2796410334 | E6: 4368333979 | F6: 4968542229
B7: Deposits | C7: 15592174400 | D7: 18833946463 | E7: 23797862764 | F7: 27147148959
B8: Borrowings | C8: 1848172073 | D8: 2067655655 | E8: 6621530751 | F8: 5479308926
B9: Other liabilities and provisions | C9: 844074643 | D9: 957222477 | E9: 1354379303 | F9: 1461285166
B10: Total | C10: 20685350503 | D10: 24660814672 | E10: 36176230869 | F10: 39101989446
B11: ASSETS | E11: 0 | F11: 0
B12: Cash and balances with Reserve Bank of India | C12: 1299956352 | D12: 1171607706 | E12: 1786832228 | F12: 1443550296
B13: Balances with banks and money at call and short notice | C13: 223312892 | D13: 766043125 | E13: 404641953 | F13: 952156416
B14: Investments | C14: 4555356930 | D14: 5170014280 | E14: 7024149587 | F14: 8363596736
B15: Advances | C15: 13688209314 | D15: 16005859000 | E15: 2.4848615e+10 | F15: 26196086171
B16: Fixed assets | C16: 60836735 | D16: 80165410 | E16: 1.1398988e+08 | F16: 136553987
B17: Other assets | C17: 857678280 | D17: 1467125151 | E17: 1998002035 | F17: 2010045840
B18: Total | C18: 20685350503 | D18: 24660814672 | E18: 36176230869 | F18: 39101989446
B19: Contingent liabilities | C19: 13954422995 | D19: 17481303179 | E19: 22967583363 | F19: 2.647417e+10
B20: Bills for collection | C20: 569680463 | D20: 714395377 | E20: 653328740 | F20: 7.0679554e+08

Sheet Cash Flow Raw Data
C2: 44651 | D2: 45016 | E2: 45382 | F2: 45747
B3: Cash flows from operating activities:
B4: Profit before income tax | C4: 490154792 | D4: 584853016 | E4: 708953051 | F4: 884780560
B5: Adjustments for:
B6: Depreciation on fixed assets | C6: 15998039 | D6: 22424793 | E6: 28100988 | F6: 33794728
B7: (Profit) / loss on revaluation of investments | C7: -15463977 | D7: 5458202 | E7: -9434922 | F7: 2683978
B8: Amortisation of premium / (discount) on investments | C8: 8213244 | D8: 8511961 | E8: 8449479 | F8: -278677
B9: Profit/ (loss) on sale of fixed assets | C9: 33388 | D9: -82875 | E9: -738174 | F9: -226517
B10: (Profit) / loss on sale of investment in subsidiary | C10: - | D10: - | E10: -73414237 | F10: 80000
B11: Provision / charge for non performing assets | C11: 106334842 | D11: 117873839 | E11: 107748189 | F11: 127153073
B12: Floating provisions | C12: - | D12: - | E12: 109000000 | F12: -
B13: Provision / (write-back) for standard assets and contingencies | C13: 49569684 | D13: 1322746 | E13: 18173261 | F13: -10658745
B14: Dividend from subsidiaries | C14: -8308954 | D14: -8109753 | E14: -13323911 | F14: -21870101
B15: Employee stock options / units expense | C15: 3259696 | D15: 7488973 | E15: 15474040 | F15: 18907034
C16: 649790754 | D16: 739740902 | E16: 898987764 | F16: 1034365333
B17: Adjustments for:
B18: Increase in investments | C18: -121951685 | D18: -633308892 | E18: -548336186 | F18: -1302003741
B19: Increase in advances | C19: -2466388983 | D19: -2435526411 | E19: -2894442171 | F19: -1489033797
B20: Increase in deposits | C20: 2241572192 | D20: 3241772063 | E20: 3391324138 | F20: 3349286195
B21: Increase in other assets | C21: -380235846 | D21: -594093460 | E21: -292254127 | F21: -73424525
B22: Increase / (decrease) in other liabilities and provisions | C22: 75178971 | D22: 109307200 | E22: -6692396 | F22: 106340648
C23: -2034597 | D23: 427891402 | E23: 548587022 | F23: 1625530113
B24: Direct taxes paid (net of refunds) | C24: -140052624 | D24: -154757324 | E24: -198437376 | F24: -173757076
B25: Net cash flows from operating activities | C25: -142087221 | D25: 273134078 | E25: 350149646 | F25: 1451773037
B26: Cash flows from investing activities:
B27: Purchase of fixed assets | C27: -21407866 | D27: -32804687 | E27: -38348940 | F27: -31986944
B28: Proceeds from sale of fixed assets | C28: 182956 | D28: 406121 | E28: 960042 | F28: 904484
B29: Investment in subsidiaries | F29: -13097695
B30: Proceeds from sale of investment in subsidiary (net) | E30: 95006717 | F30: 1920000
B31: Dividend from subsidiaries | C31: 8308954 | D31: 8109753 | E31: 13323911 | F31: 21870101
B32: Net cash flow (used in) / from investing activities | C32: -12915956 | D32: -24288813 | E32: 70941730 | F32: -20390054
B33: Cash flows from financing activities:
B34: Proceeds from exercise of convertible equity warrants | E34: 31928121
B35: Proceeds from issue of share capital other than warrants | E35: 52497323 | F35: 63464973
B36: Proceeds from issue of share capital, net of issue expenses | C36: 26097614 | D36: 34158331
B37: Proceeds from issue of Tier 1 and Tier 2 capital bonds | C37: 81627500 | D37: 230000000
B38: Redemption of Tier 1 and Tier 2 capital bonds | C38: -36500000 | D38: -114770000
B39: Increase/ (Decrease) in other borrowings | C39: 446616337 | D39: 97876082 | E39: -222750573 | F39: -1144291825
B40: Dividend paid during the year | C40: -35923960 | D40: -86045187 | E40: -84044222 | F40: -148261930
B41: Net cash flow used in financing activities | C41: 481917491 | D41: 161219226 | E41: -222369351 | F41: -1229088782
...

Sheet Assumptions
B1: Assumption Drivers
B2: Year | C2: 44651 | D2: 45016 | E2: 45382 | F2: 45747 | G2: 46112 | H2: 46477 | I2: 46843 | J2: 47208 | K2: 47573
A4: I. | B4: Schedule - Borrowing
B5: Common Equity Tier 1 capital (CET1) | C5: - | D5: - | E5: - | F5: 5087279.8 | G5: - | H5: - | I5: - | J5: - | K5: -
B6: Additional Tier 1 capital (AT1) | C6: - | D6: - | E6: - | F6: 126082.5 | G6: - | H6: - | I6: - | J6: - | K6: -
B7: Tier 1 capital (T1 = CET1 + AT1) | C7: - | D7: - | E7: - | F7: 5213362.3 | G7: - | H7: - | I7: - | J7: - | K7: -
B8: Tier 2 capital before regulatory adjustments | C8: - | D8: - | E8: - | F8: 588391.9 | G8: - | H8: - | I8: - | J8: - | K8: -
B9: Total regulatory adjustments to Tier 2 capital | C9: - | D9: - | E9: - | F9: 19.7 | G9: - | H9: - | I9: - | J9: - | K9: -
B10: Tier 2 capital (T2) | C10: - | D10: - | E10: - | F10: 588372.2 | G10: - | H10: - | I10: - | J10: - | K10: -
B11: Risk weighted Assets | C11: - | D11: - | E11: - | G11: - | H11: - | I11: - | J11: - | K11: -
