Workbook

Sheet Assumptions
A2: Assumption Drivers
C5: ='Post-Merger Actual'!F2 -> 45747 | D5: ='Post-Merger Actual'!F2+365 -> 46112 | E5: =D5+365 -> 46477 | F5: =E5+365 -> 46842
B6: Funding cost reduction (bps) | C6: - | D6: 10 | E6: 20 | F6: 30
B7: Cost synergy % | C7: 0.005
B8: Credit cost % | C8: 0.0093652071
B9: Tax rate | C9: 0.25
B11: Integration cost: Not modeled separately, assumed immaterial as management did not disclose any significant one-time restructuring expense.
B12: Funding cost reduction (bps): Gradual replacement of high-cost HDFC Ltd borrowings with lower-cost deposits.
B13: Credit cost %: Calculated in the Ratio Analysis of HDFC Bank Ltd.
B14: CASA %: Calculated in the Ratio Analysis of HDFC Bank Ltd.

Sheet Financials Raw Data
B1: HDFC BANK
B3: Profit and Loss Statement
C4: 44651 | D4: 45016 | E4: 45382 | F4: 45747
B5: I. INCOME
B6: Interest earned | C6: 1277531191 | D6: 1615855367 | E6: 2583405755 | F6: 3005170417
B7: Other income | C7: 295099004 | D7: 312148251 | E7: 492409994 | F7: 456322818
B8: Total | C8: 1572630195 | D8: 1928003618 | E8: 3075815749 | F8: 3461493235
B9: II. EXPENDITURE
B10: Interest expended | C10: 557435282 | D10: 747433173 | E10: 1498081008 | F10: 1778469527
B11: Operating expenses | C11: 374421858 | D11: 476520844 | E11: 633860240 | F11: 681748820
B12: Provisions and contingencies | C12: 271159503 | D12: 262962587 | E12: 335751716 | F12: 327801307
B13: Total | C13: 1203016643 | D13: 1486916604 | E13: 2467692964 | F13: 2788019654
B14: III. PROFIT
B15: Net profit for the year | C15: 369613552 | D15: 441087014 | E15: 608122785 | F15: 673473581
B16: Balance in the Profit and Loss account brought forward | C16: 736527947 | D16: 931856743 | E16: 1129599963 | F16: 1395798306
B17: Additions on Amalgamation (net) | E17: 35701097 | F17: -
B18: Total | C18: 1106141499 | D18: 1372943757 | E18: 1773423845 | F18: 2069271887
B19: IV. APPROPRIATIONS
B20: Transfer to Statutory Reserve | C20: 92403388 | D20: 110271754 | E20: 152030697 | F20: 168368395
B21: Transfer to General Reserve | C21: 36961355 | D21: 44108702 | E21: 60812279 | F21: 67347358
B22: Transfer to Special Reserve | D22: 5000000 | E22: 30000000 | F22: 32000000
B23: Transfer to Capital Reserve | C23: 6664722 | D23: 46127 | E23: 41664119 | F23: 5069983
B24: Transfer to / (from) Investment Reserve Account (net) | C24: 2331331 | D24: -2947976 | E24: 5294222 | F24: -
B25: Transfer to / (from) Investment Fluctuation Reserve | D25: 820000 | E25: 3780000 | F25: -
B26: Dividend pertaining to previous year paid during the year | C26: 35923960 | D26: 86045187 | E26: 84044222 | F26: 148261930
B27: Balance carried over to Balance Sheet | C27: 931856743 | D27: 1129599963 | E27: 1395798306 | F27: 1648224221
B28: Total | C28: 1106141499 | D28: 1372943757 | E28: 1773423845 | F28: 2069271887
B29: V. EARNINGS PER EQUITY SHARE (Face value ` 1/- per share) 18 (31) ` `
B30: Basic | C30: 66.8 | D30: 79.25 | E30: 85.83 | F30: 88.29
B31: Diluted | C31: 66.35 | D31: 78.89 | E31: 85.44 | F31: 87.9
B33: Weighted Average Number of Equity Shares
B34: Weighted average number of equity shares used in computing basic earnings per equity share | C34: 5533203566 | D34: 5565714265 | E34: 7084807443 | F34: 7627793180
B35: Effect of potential equity shares outstanding | C35: 37730419 | D35: 25469391 | E35: 32445707 | F35: 34177391
B36: Weighted average number of equity shares used in computing diluted earnings per equity share | C36: 5570933985 | D36: 5591183656 | E36: 7117253150 | F36: 7661970571
B38: Balane Sheet
C40: 44651 | D40: 45016 | E40: 45382 | F40: 45747
B41: CAPITAL AND LIABILITIES
B42: Capital | C42: 5545541 | D42: 5579743 | E42: 7596911 | F42: 7652222
B43: Employees stock options outstanding | E43: 26527161 | F43: 38051944
B44: Reserves and surplus | C44: 2395383846 | D44: 2796410334 | E44: 4368333979 | F44: 4968542229
...

Sheet Standalone FS-HDFC Ltd.
C2: ="Pre Merger Financial Statements - HDFC Ltd" -> Pre Merger Financial Statements - HDFC Ltd
C3: Years | D3: ='[1]Data Sheet'!H56 -> 44651 | E3: ='[1]Data Sheet'!I56 -> 45016 | F3: ='[1]Data Sheet'!J56 -> 45382 | G3: ='[1]Data Sheet'!K56 -> 45747 | I3: =G3+365 -> 46112 | J3: =I3+365 -> 46477 | K3: =J3+365 -> 46842 | L3: =K3+365 -> 47207 | M3: =L3+365 -> 47572
D4: 1 | E4: 2 | F4: 3 | G4: 4 | I4: 5 | J4: 6 | K4: 7 | L4: 8 | M4: 9
B5: # | C5: Income Statement
C6: I. INCOME
C7: Interest earned | D7: ='Financials Raw Data'!C116 -> 43297.21 | E7: ='Financials Raw Data'!D116 -> 54997.31
C8: less: Interest expended1 | D8: ='Financials Raw Data'!C128 -> 26739.21 | E8: ='Financials Raw Data'!D128 -> 35994.74
C9: Net Interest Income(NII)2 | D9: =D7-D8 -> 16558 | E9: =E7-E8 -> 19002.57
C10: Add: Other income3 | D10: =SUM('Financials Raw Data'!C117:C123,'Financials Raw Data'!C125) -> 4692.99 | E10: =SUM('Financials Raw Data'!D117:D123,'Financials Raw Data'!D125) -> 5226.34
C11: Operating Income4 | D11: =SUM(D9:D10) -> 21250.99 | E11: =SUM(E9:E10) -> 24228.91
C12: Total | D12: =SUM(D7:D10) -> 91287.41 | E12: =SUM(E7:E10) -> 115220.96
C14: II. EXPENDITURE
C15: Interest expended | D15: ='Financials Raw Data'!C128 -> 26739.21 | E15: ='Financials Raw Data'!D128 -> 35994.74
C16: Operating expenses | D16: =SUM('Financials Raw Data'!C130:C132) -> 2072.68 | E16: =SUM('Financials Raw Data'!D130:D132) -> 2419.87
C17: Provisions and contingencies | D17: ='Financials Raw Data'!C129 -> 1932 | E17: ='Financials Raw Data'!D129 -> 1795
C18: Total | D18: =SUM(D15:D17) -> 30743.89 | E18: =SUM(E15:E17) -> 40209.61
C20: III. PROFIT
C21: Net profit for the year | D21: ='Financials Raw Data'!C139 -> 13742.18 | E21: ='Financials Raw Data'!D139 -> 16239.36
C22: Balance in the Profit and Loss account brought forward | D22: 0 | E22: 0
C23: Additions on Amalgamation (net) | D23: 0 | E23: 0
C24: Total | D24: =SUM(D21:D23) -> 13742.18 | E24: =SUM(E21:E23) -> 16239.36
C26: IV. EARNINGS PER EQUITY SHARE
C27: Weighted average number of equity shares(Basic EPS) | D27: 180.8 | E27: 181.96
C28: Weighted average number of equity shares(Diluted EPS) | D28: 182.73 | E28: 183.54
C29: Basic | D29: ='Financials Raw Data'!C150 -> 76.01 | E29: ='Financials Raw Data'!D150 -> 89.24
C30: Diluted | D30: ='Financials Raw Data'!C151 -> 75.2 | E30: ='Financials Raw Data'!D151 -> 88.48
B33: # | C33: Balance Sheet
C34: CAPITAL AND LIABILITIES
C35: Capital | D35: ='Financials Raw Data'!C209 -> 362.61 | E35: ='Financials Raw Data'!D209 -> 366.91
C36: Reserves and surplus | D36: ='Financials Raw Data'!C210 -> 119888.39 | E36: ='Financials Raw Data'!D210 -> 133617.83
C37: Shareholer's Fund | D37: =SUM(D35:D36) -> 120251 | E37: =SUM(E35:E36) -> 133984.74
C38: Deposits | D38: ='Financials Raw Data'!C198 -> 160899.76 | E38: ='Financials Raw Data'!D198 -> 152111.07
C39: Deposits growth % | D39: - | E39: =E38/D38-1 -> -0.054622145
C40: Borrowings | D40: =SUM('Financials Raw Data'!C196:C197,'Financials Raw Data'!C199) -> 338781.38 | E40: =SUM('Financials Raw Data'!D196:D197,'Financials Raw Data'!D199) -> 416110.81
C41: Borrowings growth % | D41: - | E41: =E40/D40-1 -> 0.22825762
C42: Total Funding (Deposits + Borrowings) | D42: =SUM(D38,D40) -> 499681.14 | E42: =SUM(E38,E40) -> 568221.88
C43: Other liabilities and provisions | D43: =SUM('Financials Raw Data'!C200,'Financials Raw Data'!C206,'Financials Raw Data'!C185,'Financials Raw Data'!C189,'Financials Raw Data'!C191) -> 20930.32 | E43: =SUM('Financials Raw Data'!D200,'Financials Raw Data'!D206,'Financials Raw Data'!D185,'Financials Raw Data'!D189,'Financials Raw Data'!D191) -> 24567.85
C44: Total Liabilities | D44: =SUM(D37:D38,D40,D43) -> 640862.46 | E44: =SUM(E37:E38,E40,E43) -> 726774.47
C46: ASSETS
C47: Cash and Bank | D47: =SUM('Financials Raw Data'!C161:C162) -> 792.93 | E47: =SUM('Financials Raw Data'!D161:D162) -> 1217.6
...

Sheet Standalone FS-HDFC Bank
C2: ="Pre-Merger Financial Statements - HDFC BANK Ltd." -> Pre-Merger Financial Statements - HDFC BANK Ltd.
C3: Years | D3: ='[1]Data Sheet'!H56 -> 44651 | E3: ='[1]Data Sheet'!I56 -> 45016
D4: 1 | E4: 2
B5: # | C5: Income Statement
C6: I. INCOME
C7: Interest earned | D7: =IFERROR('Financials Raw Data'!C6/10000,0) -> 127753.12 | E7: =IFERROR('Financials Raw Data'!D6/10000,0) -> 161585.54
C8: less: Interest expended1 | D8: =IFERROR('Financials Raw Data'!C10/10000,0) -> 55743.528 | E8: =IFERROR('Financials Raw Data'!D10/10000,0) -> 74743.317
C9: Net Interest Income(NII)2 | D9: =D7-D8 -> 72009.591 | E9: =E7-E8 -> 86842.219
C10: Add: Other income3 | D10: =IFERROR('Financials Raw Data'!C7/10000,0) -> 29509.9 | E10: =IFERROR('Financials Raw Data'!D7/10000,0) -> 31214.825
C11: Operating Income4 | D11: =SUM(D9:D10) -> 101519.49 | E11: =SUM(E9:E10) -> 118057.04
C12: Total | D12: =SUM(D7:D10) -> 285016.14 | E12: =SUM(E7:E10) -> 354385.9
C14: II. EXPENDITURE
C15: Interest expended | D15: =IFERROR('Financials Raw Data'!C10/10000,0) -> 55743.528 | E15: =IFERROR('Financials Raw Data'!D10/10000,0) -> 74743.317
C16: Operating expenses | D16: =IFERROR('Financials Raw Data'!C11/10000,0) -> 37442.186 | E16: =IFERROR('Financials Raw Data'!D11/10000,0) -> 47652.084
C17: Provisions and contingencies | D17: =IFERROR('Financials Raw Data'!C12/10000,0) -> 27115.95 | E17: =IFERROR('Financials Raw Data'!D12/10000,0) -> 26296.259
C18: Total | D18: =SUM(D15:D17) -> 120301.66 | E18: =SUM(E15:E17) -> 148691.66
C20: III. PROFIT
C21: Net profit for the year | D21: =IFERROR('Financials Raw Data'!C15/10000,0) -> 36961.355 | E21: =IFERROR('Financials Raw Data'!D15/10000,0) -> 44108.701
C22: Balance in the Profit and Loss account brought forward | D22: =IFERROR('Financials Raw Data'!C16/10000,0) -> 73652.795 | E22: =IFERROR('Financials Raw Data'!D16/10000,0) -> 93185.674
C23: Additions on Amalgamation (net) | D23: =IFERROR('Financials Raw Data'!C17/10000,0) -> 0 | E23: =IFERROR('Financials Raw Data'!D17/10000,0) -> 0
C24: Total | D24: =SUM(D21:D23) -> 110614.15 | E24: =SUM(E21:E23) -> 137294.38
C26: IV. EARNINGS PER EQUITY SHARE
C27: Weighted average number of equity shares(Basic EPS) | D27: =IFERROR('Financials Raw Data'!C34/10000000,0) -> 553.32036 | E27: =IFERROR('Financials Raw Data'!D34/10000000,0) -> 556.57143
C28: Weighted average number of equity shares(Diluted EPS) | D28: =IFERROR('Financials Raw Data'!C36/10000000,0) -> 557.0934 | E28: =IFERROR('Financials Raw Data'!D36/10000000,0) -> 559.11837
C29: Basic | D29: =D21/D27 -> 66.799196 | E29: =E21/E27 -> 79.250747
C30: Diluted | D30: =D21/D28 -> 66.346784 | E30: =E21/E28 -> 78.889738
B32: # | C32: Balance Sheet
C33: CAPITAL AND LIABILITIES
C34: Capital | D34: =IFERROR('Financials Raw Data'!C42/10000,0) -> 554.5541 | E34: =IFERROR('Financials Raw Data'!D42/10000,0) -> 557.9743
C35: Reserves and surplus | D35: =IFERROR('Financials Raw Data'!C44/10000,0) -> 239538.38 | E35: =IFERROR('Financials Raw Data'!D44/10000,0) -> 279641.03
C36: Shareholer's Fund | D36: =SUM(D34:D35) -> 240092.94 | E36: =SUM(E34:E35) -> 280199.01
C37: Deposits | D37: =IFERROR('Financials Raw Data'!C45/10000,0) -> 1559217.4 | E37: =IFERROR('Financials Raw Data'!D45/10000,0) -> 1883394.6
C38: Deposits growth % | D38: - | E38: =E37/D37-1 -> 0.2079102
C39: Borrowings | D39: =IFERROR('Financials Raw Data'!C46/10000,0) -> 184817.21 | E39: =IFERROR('Financials Raw Data'!D46/10000,0) -> 206765.57
C40: Borrowings growth % | D40: - | E40: =E39/D39-1 -> 0.11875711
C41: Total Funding (Deposits + Borrowings) | D41: =SUM(D37,D39) -> 1744034.6 | E41: =SUM(E37,E39) -> 2090160.2
C42: Other liabilities and provisions | D42: =IFERROR('Financials Raw Data'!C47/10000,0) -> 84407.464 | E42: =IFERROR('Financials Raw Data'!D47/10000,0) -> 95722.248
C43: Total Liabilities | D43: =SUM(D36:D37,D39,D42) -> 2068535.1 | E43: =SUM(E36:E37,E39,E42) -> 2466081.5
C45: ASSETS
C46: Cash and Bank | D46: {=SUM(('Financials Raw Data'!C50:C51)/10000)} -> 152326.92 | E46: {=SUM(('Financials Raw Data'!D50:D51)/10000)} -> 193765.08
...

Sheet Pro Forma Combined Financials
C2: ="Pro Forma Combined Financial Statements - HDFC BANK Ltd." -> Pro Forma Combined Financial Statements - HDFC BANK Ltd.
C3: Years | D3: ='[1]Data Sheet'!I56 -> 45016
D4: 2 | G4: Pre- merger | H4: Pro Forma | I4: Increase/(Decrease)
C5: Income Statement | F5: Loan Book Growth | G5: ='Standalone FS-HDFC Bank'!E49 -> 154729.06 | H5: =D50 -> 2208948.6 | I5: =H5/G5-1 -> 13.276236
C6: I. INCOME | F6: Deposits Growth | G6: ='Standalone FS-HDFC Bank'!E37 -> 1883394.6 | H6: =D39 -> 2035505.7 | I6: =H6/G6-1 -> 0.08076431
C7: Interest earned | D7: =SUM('Standalone FS-HDFC Ltd.'!E7,'Standalone FS-HDFC Bank'!E7) -> 216582.85 | F7: Borrowings Growth | G7: ='Standalone FS-HDFC Bank'!E39 -> 206765.57 | H7: =D41 -> 622876.38 | I7: =H7/G7-1 -> 2.0124763
C8: less: Interest expended1 | D8: =SUM('Standalone FS-HDFC Ltd.'!E8,'Standalone FS-HDFC Bank'!E8) -> 110738.06 | F8: LDR | G8: ='Standalone FS-HDFC Bank'!E54 -> 0.082154346 | H8: =D59 -> 1.0852087 | I8: =H8-G8 -> 1.0030544
C9: Net Interest Income(NII)2 | D9: =SUM('Standalone FS-HDFC Ltd.'!E9,'Standalone FS-HDFC Bank'!E9) -> 105844.79
C10: NII Growth% | D10: =D9/'Standalone FS-HDFC Bank'!E9-1 -> 0.21881719
C11: Add: Other income3 | D11: =SUM('Standalone FS-HDFC Ltd.'!E10,'Standalone FS-HDFC Bank'!E10) -> 36441.165
C12: Operating Income4 | D12: =SUM('Standalone FS-HDFC Ltd.'!E11,'Standalone FS-HDFC Bank'!E11) -> 142285.95
C13: Total | D13: =SUM(D7:D9,D11) -> 469606.86
C15: II. EXPENDITURE
C16: Interest expended | D16: =SUM('Standalone FS-HDFC Bank'!E15,'Standalone FS-HDFC Ltd.'!E15) -> 110738.06
C17: Operating expenses | D17: =SUM('Standalone FS-HDFC Bank'!E16,'Standalone FS-HDFC Ltd.'!E16) -> 50071.954
C18: Provisions and contingencies | D18: =SUM('Standalone FS-HDFC Bank'!E17,'Standalone FS-HDFC Ltd.'!E17) -> 28091.259
C19: Total | D19: =SUM(D16:D18) -> 188901.27
C21: III. PROFIT
C22: Net profit for the year | D22: =SUM('Standalone FS-HDFC Bank'!E21,'Standalone FS-HDFC Ltd.'!E21) -> 60348.061
C23: Balance in the Profit and Loss account brought forward | D23: =SUM('Standalone FS-HDFC Bank'!E22,'Standalone FS-HDFC Ltd.'!E22) -> 93185.674
C24: Additions on Amalgamation (net) | D24: =SUM('Standalone FS-HDFC Bank'!E23,'Standalone FS-HDFC Ltd.'!E23) -> 0
C25: Total | D25: =SUM(D22:D24) -> 153533.74
C27: IV. EARNINGS PER EQUITY SHARE
C28: Weighted average number of equity shares(Basic EPS) | D28: =D61+'Standalone FS-HDFC Bank'!E27 -> 862.26423
C29: Weighted average number of equity shares(Diluted EPS) | D29: =D62+'Standalone FS-HDFC Bank'!E28 -> 867.46557
C30: Basic | D30: =D22/D28 -> 69.987899
C31: Diluted | D31: =D22/D29 -> 69.56825
C34: Balance Sheet
C35: CAPITAL AND LIABILITIES
C36: Capital | D36: =SUM('Standalone FS-HDFC Bank'!E34,'Standalone FS-HDFC Ltd.'!E35) -> 924.8843
C37: Reserves and surplus | D37: =SUM('Standalone FS-HDFC Bank'!E35,'Standalone FS-HDFC Ltd.'!E36) -> 413258.86
C38: Shareholer's Fund | D38: =SUM(D36:D37) -> 414183.75
C39: Deposits | D39: =SUM('Standalone FS-HDFC Ltd.'!E38,'Standalone FS-HDFC Bank'!E37) -> 2035505.7
C40: Deposits growth % | D40: =D39/'Standalone FS-HDFC Bank'!E37-1 -> 0.08076431
C41: Borrowings | D41: =SUM('Standalone FS-HDFC Ltd.'!E40,'Standalone FS-HDFC Bank'!E39) -> 622876.38
C42: Borrowings growth % | D42: =D41/'Standalone FS-HDFC Bank'!E39-1 -> 2.0124763
C43: Total Funding (Deposits + Borrowings) | D43: =SUM(D39,D41) -> 2658382.1
C44: Other liabilities and provisions | D44: =SUM('Standalone FS-HDFC Ltd.'!E43,'Standalone FS-HDFC Bank'!E42) -> 120290.1
C45: Total Liabilities | D45: =SUM(D38:D39,D41,D44) -> 3192855.9
C47: ASSETS
...

Sheet Post-Merger Actual
C1: ="Post-Merger Actual Financial Statements - HDFC BANK Ltd." -> Post-Merger Actual Financial Statements - HDFC BANK Ltd.
C2: Years | D2: ='Pro Forma Combined Financials'!D3 -> 45016 | E2: ='[1]Data Sheet'!J56 -> 45382 | F2: ='[1]Data Sheet'!K56 -> 45747 | G2: ='Post-Merger Actual'!F2+365 -> 46112 | H2: =G2+365 -> 46477 | I2: =H2+365 -> 46842
E3: 3 | F3: 4 | G3: 5 | H3: 6 | I3: 7
B4: # | C4: Income Statement
C5: I. INCOME
C6: Interest earned | D6: ='Pro Forma Combined Financials'!D7 -> 216582.85 | E6: =IFERROR('Financials Raw Data'!E6/10000,0) -> 258340.58 | F6: =IFERROR('Financials Raw Data'!F6/10000,0) -> 300517.04 | G6: =FORECAST(G$3,$E6:$F6,$E$3:$F$3) -> 342693.51 | H6: =FORECAST(H$3,$E6:$F6,$E$3:$F$3) -> 384869.97 | I6: =FORECAST(I$3,$E6:$F6,$E$3:$F$3) -> 427046.44
C7: less: Interest expended | D7: ='Pro Forma Combined Financials'!D8 -> 110738.06 | E7: =IFERROR('Financials Raw Data'!E10/10000,0) -> 149808.1 | F7: =IFERROR('Financials Raw Data'!F10/10000,0) -> 177846.95 | G7: =FORECAST(G$3,$E7:$F7,$E$3:$F$3) -> 205885.8 | H7: =FORECAST(H$3,$E7:$F7,$E$3:$F$3) -> 233924.66 | I7: =FORECAST(I$3,$E7:$F7,$E$3:$F$3) -> 261963.51
C8: Net Interest Income(NII) | D8: ='Pro Forma Combined Financials'!D9 -> 105844.79 | E8: =E6-E7 -> 108532.47 | F8: =F6-F7 -> 122670.09 | G8: =G6-G7 -> 136807.7 | H8: =H6-H7 -> 150945.32 | I8: =I6-I7 -> 165082.93
C9: Adjusted NII(After Synergy Impact) | G9: =G8+'Synergy Estimates'!E22 -> 137675.12 | H9: =H8+'Synergy Estimates'!E23 -> 152223.26 | I9: =I8+'Synergy Estimates'!E24 -> 166314.52
C10: NII Growth% | D10: ='Pro Forma Combined Financials'!D10 -> 0.21881719 | E10: =E8/D8-1 -> 0.025392703 | F10: =F8/E8-1 -> 0.1302616 | G10: =G8/F8-1 -> 0.11524908 | H10: =H8/G8-1 -> 0.10333931 | I10: =I8/H8-1 -> 0.093660503
C11: Add: Other income | D11: ='Pro Forma Combined Financials'!D11 -> 36441.165 | E11: =IFERROR('Financials Raw Data'!E7/10000,0) -> 49240.999 | F11: =IFERROR('Financials Raw Data'!F7/10000,0) -> 45632.282 | G11: =FORECAST(G$3,$E11:$F11,$E$3:$F$3) -> 42023.564 | H11: =FORECAST(H$3,$E11:$F11,$E$3:$F$3) -> 38414.847 | I11: =FORECAST(I$3,$E11:$F11,$E$3:$F$3) -> 34806.129
C12: Operating Income | D12: =SUM(D8,D11) -> 142285.95 | E12: =SUM(E8,E11) -> 157773.47 | F12: =SUM(F8,F11) -> 168302.37 | G12: =SUM(G8,G11) -> 178831.27 | H12: =SUM(H8,H11) -> 189360.16 | I12: =SUM(I8,I11) -> 199889.06
C13: Total | D13: ='Pro Forma Combined Financials'!D13 -> 469606.86 | E13: =SUM(E6:E8,E11) -> 565922.15 | F13: =SUM(F6:F8,F11) -> 646666.37 | G13: =SUM(G6:G8,G11) -> 727410.58 | H13: =SUM(H6:H8,H11) -> 808154.79 | I13: =SUM(I6:I8,I11) -> 888899.01
C15: II. EXPENDITURE
C16: Interest expended | D16: ='Pro Forma Combined Financials'!D16 -> 110738.06 | E16: =IFERROR('Financials Raw Data'!E10/10000,0) -> 149808.1 | F16: =IFERROR('Financials Raw Data'!F10/10000,0) -> 177846.95 | G16: =FORECAST(G$3,$E16:$F16,$E$3:$F$3) -> 205885.8 | H16: =FORECAST(H$3,$E16:$F16,$E$3:$F$3) -> 233924.66 | I16: =FORECAST(I$3,$E16:$F16,$E$3:$F$3) -> 261963.51
C17: Operating expenses | D17: ='Pro Forma Combined Financials'!D17 -> 50071.954 | E17: =IFERROR('Financials Raw Data'!E11/10000,0) -> 63386.024 | F17: =IFERROR('Financials Raw Data'!F11/10000,0) -> 68174.882 | G17: =FORECAST(G$3,$E17:$F17,$E$3:$F$3) -> 72963.74 | H17: =FORECAST(H$3,$E17:$F17,$E$3:$F$3) -> 77752.598 | I17: =FORECAST(I$3,$E17:$F17,$E$3:$F$3) -> 82541.456
C18: Adjusted Opex (After Synergy Impact) | G18: =G17-'Synergy Estimates'!E30 -> 72598.921 | H18: =H17-'Synergy Estimates'!E31 -> 77363.835 | I18: =I17-'Synergy Estimates'!E32 -> 82128.749
C19: Provisions and contingencies | D19: ='Pro Forma Combined Financials'!D18 -> 28091.259 | E19: =IFERROR('Financials Raw Data'!E12/10000,0) -> 33575.172 | F19: =IFERROR('Financials Raw Data'!F12/10000,0) -> 32780.131 | G19: =FORECAST(G$3,$E19:$F19,$E$3:$F$3) -> 31985.09 | H19: =FORECAST(H$3,$E19:$F19,$E$3:$F$3) -> 31190.049 | I19: =FORECAST(I$3,$E19:$F19,$E$3:$F$3) -> 30395.008
C20: Total | D20: =SUM(D16:D17,D19) -> 188901.27 | E20: =SUM(E16:E17,E19) -> 246769.3 | F20: =SUM(F16:F17,F19) -> 278801.97 | G20: =SUM(G16:G17,G19) -> 310834.63 | H20: =SUM(H16:H17,H19) -> 342867.3 | I20: =SUM(I16:I17,I19) -> 374899.97
C22: III. PROFIT
C23: Net profit for the year | D23: ='Pro Forma Combined Financials'!D22 -> 60348.061 | E23: =IFERROR('Financials Raw Data'!E15/10000,0) -> 60812.279 | F23: =IFERROR('Financials Raw Data'!F15/10000,0) -> 67347.358 | G23: =FORECAST(G$3,$E23:$F23,$E$3:$F$3) -> 73882.438 | H23: =FORECAST(H$3,$E23:$F23,$E$3:$F$3) -> 80417.517 | I23: =FORECAST(I$3,$E23:$F23,$E$3:$F$3) -> 86952.597
C24: Adjusted PAT (After Synergy Impact) | G24: =G23+'Synergy Estimates'!E43 -> 74806.615 | H24: =H23+'Synergy Estimates'!E44 -> 81667.549 | I24: =I23+'Synergy Estimates'!E45 -> 88185.817
C25: Balance in the Profit and Loss account brought forward | D25: ='Pro Forma Combined Financials'!D23 -> 93185.674 | E25: =IFERROR('Financials Raw Data'!E16/10000,0) -> 112960 | F25: =IFERROR('Financials Raw Data'!F16/10000,0) -> 139579.83 | G25: =FORECAST(G$3,$E25:$F25,$E$3:$F$3) -> 166199.66 | H25: =FORECAST(H$3,$E25:$F25,$E$3:$F$3) -> 192819.5 | I25: =FORECAST(I$3,$E25:$F25,$E$3:$F$3) -> 219439.33
C26: Additions on Amalgamation (net) | D26: ='Pro Forma Combined Financials'!D24 -> 0 | E26: =IFERROR('Financials Raw Data'!E17/10000,0) -> 3570.1097 | F26: =IFERROR('Financials Raw Data'!F17/10000,0) -> 0 | G26: =FORECAST(G$3,$E26:$F26,$E$3:$F$3) -> -3570.1097 | H26: =FORECAST(H$3,$E26:$F26,$E$3:$F$3) -> -7140.2194 | I26: =FORECAST(I$3,$E26:$F26,$E$3:$F$3) -> -10710.329
C27: Total | D27: ='Pro Forma Combined Financials'!D25 -> 153533.74 | E27: =SUM(E23:E26) -> 177342.38 | F27: =SUM(F23:F26) -> 206927.19 | G27: =SUM(G23:G26) -> 311318.61 | H27: =SUM(H23:H26) -> 347764.35 | I27: =SUM(I23:I26) -> 383867.42
C29: IV. EARNINGS PER EQUITY SHARE
C30: Weighted average number of equity shares(Basic EPS) | D30: ='Pro Forma Combined Financials'!D28 -> 862.26423 | E30: =IFERROR('Financials Raw Data'!E34/10000000,0) -> 708.48074 | F30: =IFERROR('Financials Raw Data'!F34/10000000,0) -> 762.77932 | G30: =F30*(1+'Post-Merger Actual'!$D$64) -> 766.59321 | H30: =G30*(1+'Post-Merger Actual'!$D$64) -> 770.42618 | I30: =H30*(1+'Post-Merger Actual'!$D$64) -> 774.27831
C31: Weighted average number of equity shares(Diluted EPS) | D31: ='Pro Forma Combined Financials'!D29 -> 867.46557 | E31: =IFERROR('Financials Raw Data'!E36/10000000,0) -> 711.72532 | F31: =IFERROR('Financials Raw Data'!F36/10000000,0) -> 766.19706 | G31: =F31*(1+'Post-Merger Actual'!$D$64) -> 770.02804 | H31: =G31*(1+'Post-Merger Actual'!$D$64) -> 773.87818 | I31: =H31*(1+'Post-Merger Actual'!$D$64) -> 777.74757
C32: Basic | D32: ='Pro Forma Combined Financials'!D30 -> 69.987899 | E32: =E23/E30 -> 85.834765 | F32: =F23/F30 -> 88.292061 | G32: =G24/G30 -> 97.583195 | H32: =H24/H30 -> 106.00308 | I32: =I24/I30 -> 113.89421
C33: Diluted | D33: ='Pro Forma Combined Financials'!D31 -> 69.56825 | E33: =E23/E31 -> 85.443467 | F33: =F23/F31 -> 87.898221 | G33: =G24/G31 -> 97.14791 | H33: =H24/H31 -> 105.53024 | I33: =I24/I31 -> 113.38617
B36: # | C36: Balance Sheet
C37: CAPITAL AND LIABILITIES
C38: Capital | D38: ='Pro Forma Combined Financials'!D36 -> 924.8843 | E38: =IFERROR('Financials Raw Data'!E42/10000,0) -> 759.6911 | F38: =IFERROR('Financials Raw Data'!F42/10000,0) -> 765.2222 | G38: =FORECAST(G$3,$E38:$F38,$E$3:$F$3) -> 770.7533 | H38: =FORECAST(H$3,$E38:$F38,$E$3:$F$3) -> 776.2844 | I38: =FORECAST(I$3,$E38:$F38,$E$3:$F$3) -> 781.8155
C39: Reserves and surplus | D39: ='Pro Forma Combined Financials'!D37 -> 413258.86 | E39: =IFERROR('Financials Raw Data'!E44/10000,0) -> 436833.4 | F39: =IFERROR('Financials Raw Data'!F44/10000,0) -> 496854.22 | G39: =FORECAST(G$3,$E39:$F39,$E$3:$F$3) -> 556875.05 | H39: =FORECAST(H$3,$E39:$F39,$E$3:$F$3) -> 616895.87 | I39: =FORECAST(I$3,$E39:$F39,$E$3:$F$3) -> 676916.7
C40: Shareholer's Fund | D40: ='Pro Forma Combined Financials'!D38 -> 414183.75 | E40: =SUM(E38:E39) -> 437593.09 | F40: =SUM(F38:F39) -> 497619.45 | G40: =SUM(G38:G39) -> 557645.8 | H40: =SUM(H38:H39) -> 617672.16 | I40: =SUM(I38:I39) -> 677698.51
C41: Deposits | D41: ='Pro Forma Combined Financials'!D39 -> 2035505.7 | E41: =IFERROR('Financials Raw Data'!E45/10000,0) -> 2379786.3 | F41: =IFERROR('Financials Raw Data'!F45/10000,0) -> 2714714.9 | G41: =FORECAST(G$3,$E41:$F41,$E$3:$F$3) -> 3049643.5 | H41: =FORECAST(H$3,$E41:$F41,$E$3:$F$3) -> 3384572.1 | I41: =FORECAST(I$3,$E41:$F41,$E$3:$F$3) -> 3719500.8
C42: Deposits growth % | D42: - | E42: =E41/D41-1 -> 0.1691376 | F42: =F41/E41-1 -> 0.14073895 | G42: =G41/F41-1 -> 0.12337525 | H42: =H41/G41-1 -> 0.1098255 | I42: =I41/H41-1 -> 0.098957448
C43: Borrowings | D43: ='Pro Forma Combined Financials'!D41 -> 622876.38 | E43: =IFERROR('Financials Raw Data'!E46/10000,0) -> 662153.08 | F43: =IFERROR('Financials Raw Data'!F46/10000,0) -> 547930.89 | G43: =FORECAST(G$3,$E43:$F43,$E$3:$F$3) -> 433708.71 | H43: =FORECAST(H$3,$E43:$F43,$E$3:$F$3) -> 319486.53 | I43: =FORECAST(I$3,$E43:$F43,$E$3:$F$3) -> 205264.35
C44: Borrowings growth % | D44: - | E44: =E43/D43-1 -> 0.063056974 | F44: =F43/E43-1 -> -0.17250117 | G44: =G43/F43-1 -> -0.20846093 | H44: =H43/G43-1 -> -0.26336151 | I44: =I43/H43-1 -> -0.35751799
C45: Other liabilities and provisions | D45: ='Pro Forma Combined Financials'!D44 -> 120290.1 | E45: =IFERROR('Financials Raw Data'!E47/10000,0) -> 135437.93 | F45: =IFERROR('Financials Raw Data'!F47/10000,0) -> 146128.52 | G45: =FORECAST(G$3,$E45:$F45,$E$3:$F$3) -> 156819.1 | H45: =FORECAST(H$3,$E45:$F45,$E$3:$F$3) -> 167509.69 | I45: =FORECAST(I$3,$E45:$F45,$E$3:$F$3) -> 178200.28
...

Sheet Synergy Estimates
B2: Synergy Estimates
B4: A. | C4: FUNDING SYNERGY
C6: # Forecasted Borrowings taken as Base Borrowings for FY26, FY27, and FY28
C7: Borrowing Replacement Assumption
C8: Year | D8: % Replaced
C9: =Assumptions!D5 -> 46112 | D9: 0.1
C10: =Assumptions!E5 -> 46477 | D10: 0.2
C11: =Assumptions!F5 -> 46842 | D11: 0.3
C13: Rate Difference
C14: Assume
C15: Borrowing cost | D15: 0.075
C16: Deposit cost | D16: 0.055
C17: Rate Diff | D17: 0.02
C19: Interest Savings Calculation
C20: Year | D20: Borrowings Replaced | E20: Interest Saving
C21: =C29 -> 45747 | D21: - | E21: -
C22: =C9 -> 46112 | D22: ='Post-Merger Actual'!G43*D9 -> 43370.871 | E22: =D22*$D$17 -> 867.41742
C23: =C10 -> 46477 | D23: ='Post-Merger Actual'!H43*D10 -> 63897.306 | E23: =D23*$D$17 -> 1277.9461
C24: =C11 -> 46842 | D24: ='Post-Merger Actual'!I43*D11 -> 61579.304 | E24: =D24*$D$17 -> 1231.5861
B26: B. | C26: COST SYNERGY
C27: Cost Synergy | D27: =Assumptions!C7 -> 0.005
C28: Year | D28: Operating Expenses | E28: Cost Savings
C29: ='Post-Merger Actual'!F2 -> 45747 | D29: ='Post-Merger Actual'!F17 -> 68174.882 | E29: =D29*$D$27 -> 340.87441
C30: =C22 -> 46112 | D30: ='Post-Merger Actual'!G17 -> 72963.74 | E30: =D30*$D$27 -> 364.8187
C31: =C23 -> 46477 | D31: ='Post-Merger Actual'!H17 -> 77752.598 | E31: =D31*$D$27 -> 388.76299
C32: =C24 -> 46842 | D32: ='Post-Merger Actual'!I17 -> 82541.456 | E32: =D32*$D$27 -> 412.70728
B34: C. | C34: TOTAL SYNERGY IMPACT
C36: Year | D36: Funding Benefit | E36: Cost Benefit | F36: Total Synergy
C37: =C30 -> 46112 | D37: =E22 -> 867.41742 | E37: =E30 -> 364.8187 | F37: =SUM(D37:E37) -> 1232.2361
C38: =C31 -> 46477 | D38: =E23 -> 1277.9461 | E38: =E31 -> 388.76299 | F38: =SUM(D38:E38) -> 1666.7091
C39: =C32 -> 46842 | D39: =E24 -> 1231.5861 | E39: =E32 -> 412.70728 | F39: =SUM(D39:E39) -> 1644.2934
C41: Tax Rate | D41: =Assumptions!C9 -> 0.25
C42: =C36 -> Year | D42: =F36 -> Total Synergy | E42: After-Tax Synergy
C43: =C37 -> 46112 | D43: =F37 -> 1232.2361 | E43: =D43*(1-$D$41) -> 924.17709
C44: =C38 -> 46477 | D44: =F38 -> 1666.7091 | E44: =D44*(1-$D$41) -> 1250.0318
C45: =C39 -> 46842 | D45: =F39 -> 1644.2934 | E45: =D45*(1-$D$41) -> 1233.22

Sheet Merger Impact Analysis
C2: Merger Impact / EPS Improvement Analysis
C4: EPS Trend
D5: ='Post-Merger Actual'!D2 -> 45016 | E5: ='Post-Merger Actual'!E2 -> 45382 | F5: ='Post-Merger Actual'!F2 -> 45747 | G5: ='Post-Merger Actual'!G2 -> 46112 | H5: ='Post-Merger Actual'!H2 -> 46477 | I5: ='Post-Merger Actual'!I2 -> 46842
C7: EPS Diluted | D7: ='Post-Merger Actual'!D33 -> 69.56825 | E7: ='Post-Merger Actual'!E33 -> 85.443467 | F7: ='Post-Merger Actual'!F33 -> 87.898221 | G7: ='Post-Merger Actual'!G33 -> 97.14791 | H7: ='Post-Merger Actual'!H33 -> 105.53024 | I7: ='Post-Merger Actual'!I33 -> 113.38617
C9: Improvement % | D9: =I7/D7-1 -> 0.62985511
C11: Merger Impact Summary
D13: =D5 -> 45016 | E13: =I5 -> 46842 | F13: Change
C14: EPS | D14: =D7 -> 69.56825 | E14: =I7 -> 113.38617 | F14: =D9 -> 0.62985511
C15: NIM | D15: ='Post-Merger Actual'!D58 -> 0.047916366 | E15: ='Post-Merger Actual'!I58 -> 0.047699705 | F15: -2 bps
C16: LDR | D16: ='Post-Merger Actual'!D57 -> 1.0852087 | E16: ='Post-Merger Actual'!I57 -> 0.9374105 | F16: Normalised
C17: Loan Book | D17: ='Post-Merger Actual'!D51/100000 -> 22.089486 | E17: ='Post-Merger Actual'!I51/100000 -> 34.866991 | F17: =((E17/D17)^(1/5))-1 -> 0.095584229
C20: 1. NIM remains stable as funding cost benefits are offset by balance sheet normalisation and competitive pressures.
C21: 2. EPS expected to grow ~63% over five years
C22: 3. LDR normalises to ~94% as borrowings decline
C23: 4.Merger value creation is driven by replacement of high-cost borrowings with deposits and ~10% loan growth.
C24: 5. NIM expansion is limited, indicating that earnings growth is driven by scale rather than margin expansion.
